Workbook

Sheet Info List
A1: STUDENT INFORMATION LIST
A2: ID | B2: NAME OF STUDENT | C2: FORM | D2: NO. ON ROLL | E2: TERM | F2: ATT. | G2: TOTAL ATT.
A3: BHS9001 | B3: ABRAKWAH EVA OWUSUAA | C3: 9 | D3: =COUNTA(B3:B31) -> 29 | E3: 1
A4: BHS9002 | B4: ADZILAFU EDWARD | C4: 9 | E4: 1
A5: BHS9003 | B5: AGYEPONG DASEBRE | C5: 9 | E5: 1
A6: BHS9004 | B6: ANIWA JOANA SEYRAM | C6: 9 | E6: 1
A7: BHS9005 | B7: ANNAN AGNES | C7: 9 | E7: 1
A8: BHS9006 | B8: ARTHUR LILLIAN ABENA | C8: 9 | E8: 1
A9: BHS9007 | B9: ASARE JACOB | C9: 9 | E9: 1
A10: BHS9008 | B10: BAAH JOSEPHINE KONADU | C10: 9 | E10: 1
A11: BHS9009 | B11: BAIDOO MIDRED | C11: 9 | E11: 1
A12: BHS9010 | B12: BOAKYE KELVIN OWUSU | C12: 9 | E12: 1
A13: BHS9011 | B13: BOATENG NICHOLAS KELVIN | C13: 9 | E13: 1
A14: BHS9012 | B14: CHARKITEY JOSEPH TETTEY EMEKOH | C14: 9 | E14: 1
A15: BHS9013 | B15: DANKWAH AMA JANEL | C15: 9 | E15: 1
... A31: BHS9029 | B31: YEVAKPOR SYLVIA EYRAM | C31: 9 | E31: 1

Sheet ENGLISH
A1: ENGLISH LANGUAGE
A2: ID | B2: NAME OF STUDENT | C2: FORM | D2: TOTAL | E2: CLASS SCORE | F2: TOTAL EXAMS SCORE | G2: EXAMS SCORE | H2: OVERALL SCORE | I2: POSITION IN SUBJECT | J2: GRADE | K2: REMARKS
D3: 1 | E3: 50% (A) | F3: 1 | G3: 50% (B) | H3: 100% (A + B)
A4: ='Info List'!A3 -> BHS9001 | B4: ='Info List'!B3 -> ABRAKWAH EVA OWUSUAA | C4: ='Info List'!C3 -> 9 | D4: 89 | E4: =0.5*D4 -> 44.5 | F4: 96 | G4: =0.5*F4 -> 48 | H4: =E4+G4 -> 92.5 | I4: =RANK(H4,$H$4:$H$32) -> 1 | J4: =IF(H4>79.5, 1, IF(H4>69.5, 2, IF(H4>59.5, 3, IF(H4>54.5, 4, IF(H4>49.5, 5, IF(H4>44.5, 6, IF(H4>39.5, 7, IF(H4>33.5, 8, IF(H4>-1, 9))))))))) -> 1 | K4: =VLOOKUP(H4,'GRADING SYSTEM'!$D$15:$F$23,3) -> EXCELLENT
A5: ='Info List'!A4 -> BHS9002 | B5: ='Info List'!B4 -> ADZILAFU EDWARD | C5: ='Info List'!C4 -> 9 | D5: 70 | E5: =0.5*D5 -> 35 | G5: =0.5*F5 -> 0 | H5: =E5+G5 -> 35 | I5: =RANK(H5,$H$4:$H$32) -> 29 | J5: =IF(H5>79.5, 1, IF(H5>69.5, 2, IF(H5>59.5, 3, IF(H5>54.5, 4, IF(H5>49.5, 5, IF(H5>44.5, 6, IF(H5>39.5, 7, IF(H5>33.5, 8, IF(H5>-1, 9))))))))) -> 8 | K5: =VLOOKUP(H5,'GRADING SYSTEM'!$D$15:$F$23,3) -> WEAK PASS
A6: ='Info List'!A5 -> BHS9003 | B6: ='Info List'!B5 -> AGYEPONG DASEBRE | C6: ='Info List'!C5 -> 9 | D6: 71 | E6: =0.5*D6 -> 35.5 | G6: 0 | H6: =E6+G6 -> 35.5 | I6: =RANK(H6,$H$4:$H$32) -> 28 | J6: =IF(H6>79.5, 1, IF(H6>69.5, 2, IF(H6>59.5, 3, IF(H6>54.5, 4, IF(H6>49.5, 5, IF(H6>44.5, 6, IF(H6>39.5, 7, IF(H6>33.5, 8, IF(H6>-1, 9))))))))) -> 8 | K6: =VLOOKUP(H6,'GRADING SYSTEM'!$D$15:$F$23,3) -> WEAK PASS
A7: ='Info List'!A6 -> BHS9004 | B7: ='Info List'!B6 -> ANIWA JOANA SEYRAM | C7: ='Info List'!C6 -> 9 | D7: 72 | E7: =0.5*D7 -> 36 | G7: =0.5*F7 -> 0 | H7: =E7+G7 -> 36 | I7: =RANK(H7,$H$4:$H$32) -> 27 | J7: =IF(H7>79.5, 1, IF(H7>69.5, 2, IF(H7>59.5, 3, IF(H7>54.5, 4, IF(H7>49.5, 5, IF(H7>44.5, 6, IF(H7>39.5, 7, IF(H7>33.5, 8, IF(H7>-1, 9))))))))) -> 8 | K7: =VLOOKUP(H7,'GRADING SYSTEM'!$D$15:$F$23,3) -> WEAK PASS
A8: ='Info List'!A7 -> BHS9005 | B8: ='Info List'!B7 -> ANNAN AGNES | C8: ='Info List'!C7 -> 9 | D8: 73 | E8: =0.5*D8 -> 36.5 | G8: =0.5*F8 -> 0 | H8: =E8+G8 -> 36.5 | I8: =RANK(H8,$H$4:$H$32) -> 26 | J8: =IF(H8>79.5, 1, IF(H8>69.5, 2, IF(H8>59.5, 3, IF(H8>54.5, 4, IF(H8>49.5, 5, IF(H8>44.5, 6, IF(H8>39.5, 7, IF(H8>33.5, 8, IF(H8>-1, 9))))))))) -> 8 | K8: =VLOOKUP(H8,'GRADING SYSTEM'!$D$15:$F$23,3) -> WEAK PASS
A9: ='Info List'!A8 -> BHS9006 | B9: ='Info List'!B8 -> ARTHUR LILLIAN ABENA | C9: ='Info List'!C8 -> 9 | D9: 74 | E9: =0.5*D9 -> 37 | G9: =0.5*F9 -> 0 | H9: =E9+G9 -> 37 | I9: =RANK(H9,$H$4:$H$32) -> 25 | J9: =IF(H9>79.5, 1, IF(H9>69.5, 2, IF(H9>59.5, 3, IF(H9>54.5, 4, IF(H9>49.5, 5, IF(H9>44.5, 6, IF(H9>39.5, 7, IF(H9>33.5, 8, IF(H9>-1, 9))))))))) -> 8 | K9: =VLOOKUP(H9,'GRADING SYSTEM'!$D$15:$F$23,3) -> WEAK PASS
A10: ='Info List'!A9 -> BHS9007 | B10: ='Info List'!B9 -> ASARE JACOB | C10: ='Info List'!C9 -> 9 | D10: 75 | E10: =0.5*D10 -> 37.5 | G10: =0.5*F10 -> 0 | H10: =E10+G10 -> 37.5 | I10: =RANK(H10,$H$4:$H$32) -> 24 | J10: =IF(H10>79.5, 1, IF(H10>69.5, 2, IF(H10>59.5, 3, IF(H10>54.5, 4, IF(H10>49.5, 5, IF(H10>44.5, 6, IF(H10>39.5, 7, IF(H10>33.5, 8, IF(H10>-1, 9))))))))) -> 8 | K10: =VLOOKUP(H10,'GRADING SYSTEM'!$D$15:$F$23,3) -> WEAK PASS
A11: ='Info List'!A10 -> BHS9008 | B11: ='Info List'!B10 -> BAAH JOSEPHINE KONADU | C11: ='Info List'!C10 -> 9 | D11: 76 | E11: =0.5*D11 -> 38 | G11: =0.5*F11 -> 0 | H11: =E11+G11 -> 38 | I11: =RANK(H11,$H$4:$H$32) -> 23 | J11: =IF(H11>79.5, 1, IF(H11>69.5, 2, IF(H11>59.5, 3, IF(H11>54.5, 4, IF(H11>49.5, 5, IF(H11>44.5, 6, IF(H11>39.5, 7, IF(H11>33.5, 8, IF(H11>-1, 9))))))))) -> 8 | K11: =VLOOKUP(H11,'GRADING SYSTEM'!$D$15:$F$23,3) -> WEAK PASS
A12: ='Info List'!A11 -> BHS9009 | B12: ='Info List'!B11 -> BAIDOO MIDRED | C12: ='Info List'!C11 -> 9 | D12: 77 | E12: =0.5*D12 -> 38.5 | G12: =0.5*F12 -> 0 | H12: =E12+G12 -> 38.5 | I12: =RANK(H12,$H$4:$H$32) -> 22 | J12: =IF(H12>79.5, 1, IF(H12>69.5, 2, IF(H12>59.5, 3, IF(H12>54.5, 4, IF(H12>49.5, 5, IF(H12>44.5, 6, IF(H12>39.5, 7, IF(H12>33.5, 8, IF(H12>-1, 9))))))))) -> 8 | K12: =VLOOKUP(H12,'GRADING SYSTEM'!$D$15:$F$23,3) -> WEAK PASS
A13: ='Info List'!A12 -> BHS9010 | B13: ='Info List'!B12 -> BOAKYE KELVIN OWUSU | C13: ='Info List'!C12 -> 9 | D13: 78 | E13: =0.5*D13 -> 39 | G13: =0.5*F13 -> 0 | H13: =E13+G13 -> 39 | I13: =RANK(H13,$H$4:$H$32) -> 21 | J13: =IF(H13>79.5, 1, IF(H13>69.5, 2, IF(H13>59.5, 3, IF(H13>54.5, 4, IF(H13>49.5, 5, IF(H13>44.5, 6, IF(H13>39.5, 7, IF(H13>33.5, 8, IF(H13>-1, 9))))))))) -> 8 | K13: =VLOOKUP(H13,'GRADING SYSTEM'!$D$15:$F$23,3) -> WEAK PASS
A14: ='Info List'!A13 -> BHS9011 | B14: ='Info List'!B13 -> BOATENG NICHOLAS KELVIN | C14: ='Info List'!C13 -> 9 | D14: 79 | E14: =0.5*D14 -> 39.5 | G14: =0.5*F14 -> 0 | H14: =E14+G14 -> 39.5 | I14: =RANK(H14,$H$4:$H$32) -> 20 | J14: =IF(H14>79.5, 1, IF(H14>69.5, 2, IF(H14>59.5, 3, IF(H14>54.5, 4, IF(H14>49.5, 5, IF(H14>44.5, 6, IF(H14>39.5, 7, IF(H14>33.5, 8, IF(H14>-1, 9))))))))) -> 8 | K14: =VLOOKUP(H14,'GRADING SYSTEM'!$D$15:$F$23,3) -> WEAK PASS
A15: ='Info List'!A14 -> BHS9012 | B15: ='Info List'!B14 -> CHARKITEY JOSEPH TETTEY EMEKOH | C15: ='Info List'!C14 -> 9 | D15: 80 | E15: =0.5*D15 -> 40 | G15: =0.5*F15 -> 0 | H15: =E15+G15 -> 40 | I15: =RANK(H15,$H$4:$H$32) -> 19 | J15: =IF(H15>79.5, 1, IF(H15>69.5, 2, IF(H15>59.5, 3, IF(H15>54.5, 4, IF(H15>49.5, 5, IF(H15>44.5, 6, IF(H15>39.5, 7, IF(H15>33.5, 8, IF(H15>-1, 9))))))))) -> 7 | K15: =VLOOKUP(H15,'GRADING SYSTEM'!$D$15:$F$23,3) -> PASS
A16: ='Info List'!A15 -> BHS9013 | B16: ='Info List'!B15 -> DANKWAH AMA JANEL | C16: ='Info List'!C15 -> 9 | D16: 81 | E16: =0.5*D16 -> 40.5 | G16: =0.5*F16 -> 0 | H16: =E16+G16 -> 40.5 | I16: =RANK(H16,$H$4:$H$32) -> 18 | J16: =IF(H16>79.5, 1, IF(H16>69.5, 2, IF(H16>59.5, 3, IF(H16>54.5, 4, IF(H16>49.5, 5, IF(H16>44.5, 6, IF(H16>39.5, 7, IF(H16>33.5, 8, IF(H16>-1, 9))))))))) -> 7 | K16: =VLOOKUP(H16,'GRADING SYSTEM'!$D$15:$F$23,3) -> PASS
A17: ='Info List'!A16 -> BHS9014 | B17: ='Info List'!B16 -> DANKWAH SHANTEL | C17: ='Info List'!C16 -> 9 | D17: 82 | E17: =0.5*D17 -> 41 | G17: =0.5*F17 -> 0 | H17: =E17+G17 -> 41 | I17: =RANK(H17,$H$4:$H$32) -> 17 | J17: =IF(H17>79.5, 1, IF(H17>69.5, 2, IF(H17>59.5, 3, IF(H17>54.5, 4, IF(H17>49.5, 5, IF(H17>44.5, 6, IF(H17>39.5, 7, IF(H17>33.5, 8, IF(H17>-1, 9))))))))) -> 7 | K17: =VLOOKUP(H17,'GRADING SYSTEM'!$D$15:$F$23,3) -> PASS
A18: ='Info List'!A17 -> BHS9015 | B18: ='Info List'!B17 -> ESSILFIE ENOCH | C18: ='Info List'!C17 -> 9 | D18: 83 | E18: =0.5*D18 -> 41.5 | G18: =0.5*F18 -> 0 | H18: =E18+G18 -> 41.5 | I18: =RANK(H18,$H$4:$H$32) -> 16 | J18: =IF(H18>79.5, 1, IF(H18>69.5, 2, IF(H18>59.5, 3, IF(H18>54.5, 4, IF(H18>49.5, 5, IF(H18>44.5, 6, IF(H18>39.5, 7, IF(H18>33.5, 8, IF(H18>-1, 9))))))))) -> 7 | K18: =VLOOKUP(H18,'GRADING SYSTEM'!$D$15:$F$23,3) -> PASS
... A32: ='Info List'!A31 -> BHS9029 | B32: ='Info List'!B31 -> YEVAKPOR SYLVIA EYRAM | C32: ='Info List'!C31 -> 9 | D32: 97 | E32: =0.5*D32 -> 48.5 | G32: =0.5*F32 -> 0 | H32: =E32+G32 -> 48.5 | I32: =RANK(H32,$H$4:$H$32) -> 2 | J32: =IF(H32>79.5, 1, IF(H32>69.5, 2, IF(H32>59.5, 3, IF(H32>54.5, 4, IF(H32>49.5, 5, IF(H32>44.5, 6, IF(H32>39.5, 7, IF(H32>33.5, 8, IF(H32>-1, 9))))))))) -> 6 | K32: =VLOOKUP(H32,'GRADING SYSTEM'!$D$15:$F$23,3) -> LOW AVERAGE

Sheet MATHS
A1: MATHEMATICS
A2: ID | B2: NAME OF STUDENT | C2: FORM | D2: TOTAL | E2: CLASS SCORE | F2: TOTAL EXAMS SCORE | G2: EXAMS SCORE | H2: OVERALL SCORE | I2: POSITION IN SUBJECT | J2: GRADE | K2: REMARKS
D3: 1 | E3: 50% (A) | F3: 1 | G3: 50% (B) | H3: 100% (A + B)
A4: ='Info List'!A3 -> BHS9001 | B4: ='Info List'!B3 -> ABRAKWAH EVA OWUSUAA | C4: ='Info List'!C3 -> 9 | D4: 78 | E4: =0.5*D4 -> 39 | F4: 85 | G4: =0.5*F4 -> 42.5 | H4: =E4+G4 -> 81.5 | I4: =RANK(H4,$H$4:$H$32) -> 1 | J4: =IF(H4>79.5, 1, IF(H4>69.5, 2, IF(H4>59.5, 3, IF(H4>54.5, 4, IF(H4>49.5, 5, IF(H4>44.5, 6, IF(H4>39.5, 7, IF(H4>33.5, 8, IF(H4>-1, 9))))))))) -> 1 | K4: =VLOOKUP(H4,'GRADING SYSTEM'!$D$15:$F$23,3) -> EXCELLENT
A5: ='Info List'!A4 -> BHS9002 | B5: ='Info List'!B4 -> ADZILAFU EDWARD | C5: ='Info List'!C4 -> 9 | D5: 70 | E5: =0.5*D5 -> 35 | G5: =0.5*F5 -> 0 | H5: =E5+G5 -> 35 | I5: =RANK(H5,$H$4:$H$32) -> 29 | J5: =IF(H5>79.5, 1, IF(H5>69.5, 2, IF(H5>59.5, 3, IF(H5>54.5, 4, IF(H5>49.5, 5, IF(H5>44.5, 6, IF(H5>39.5, 7, IF(H5>33.5, 8, IF(H5>-1, 9))))))))) -> 8 | K5: =VLOOKUP(H5,'GRADING SYSTEM'!$D$15:$F$23,3) -> WEAK PASS
A6: ='Info List'!A5 -> BHS9003 | B6: ='Info List'!B5 -> AGYEPONG DASEBRE | C6: ='Info List'!C5 -> 9 | D6: 71 | E6: =0.5*D6 -> 35.5 | G6: =0.5*F6 -> 0 | H6: =E6+G6 -> 35.5 | I6: =RANK(H6,$H$4:$H$32) -> 28 | J6: =IF(H6>79.5, 1, IF(H6>69.5, 2, IF(H6>59.5, 3, IF(H6>54.5, 4, IF(H6>49.5, 5, IF(H6>44.5, 6, IF(H6>39.5, 7, IF(H6>33.5, 8, IF(H6>-1, 9))))))))) -> 8 | K6: =VLOOKUP(H6,'GRADING SYSTEM'!$D$15:$F$23,3) -> WEAK PASS
A7: ='Info List'!A6 -> BHS9004 | B7: ='Info List'!B6 -> ANIWA JOANA SEYRAM | C7: ='Info List'!C6 -> 9 | D7: 72 | E7: =0.5*D7 -> 36 | G7: =0.5*F7 -> 0 | H7: =E7+G7 -> 36 | I7: =RANK(H7,$H$4:$H$32) -> 27 | J7: =IF(H7>79.5, 1, IF(H7>69.5, 2, IF(H7>59.5, 3, IF(H7>54.5, 4, IF(H7>49.5, 5, IF(H7>44.5, 6, IF(H7>39.5, 7, IF(H7>33.5, 8, IF(H7>-1, 9))))))))) -> 8 | K7: =VLOOKUP(H7,'GRADING SYSTEM'!$D$15:$F$23,3) -> WEAK PASS
A8: ='Info List'!A7 -> BHS9005 | B8: ='Info List'!B7 -> ANNAN AGNES | C8: ='Info List'!C7 -> 9 | D8: 73 | E8: =0.5*D8 -> 36.5 | G8: =0.5*F8 -> 0 | H8: =E8+G8 -> 36.5 | I8: =RANK(H8,$H$4:$H$32) -> 26 | J8: =IF(H8>79.5, 1, IF(H8>69.5, 2, IF(H8>59.5, 3, IF(H8>54.5, 4, IF(H8>49.5, 5, IF(H8>44.5, 6, IF(H8>39.5, 7, IF(H8>33.5, 8, IF(H8>-1, 9))))))))) -> 8 | K8: =VLOOKUP(H8,'GRADING SYSTEM'!$D$15:$F$23,3) -> WEAK PASS
A9: ='Info List'!A8 -> BHS9006 | B9: ='Info List'!B8 -> ARTHUR LILLIAN ABENA | C9: ='Info List'!C8 -> 9 | D9: 74 | E9: =0.5*D9 -> 37 | G9: =0.5*F9 -> 0 | H9: =E9+G9 -> 37 | I9: =RANK(H9,$H$4:$H$32) -> 25 | J9: =IF(H9>79.5, 1, IF(H9>69.5, 2, IF(H9>59.5, 3, IF(H9>54.5, 4, IF(H9>49.5, 5, IF(H9>44.5, 6, IF(H9>39.5, 7, IF(H9>33.5, 8, IF(H9>-1, 9))))))))) -> 8 | K9: =VLOOKUP(H9,'GRADING SYSTEM'!$D$15:$F$23,3) -> WEAK PASS
A10: ='Info List'!A9 -> BHS9007 | B10: ='Info List'!B9 -> ASARE JACOB | C10: ='Info List'!C9 -> 9 | D10: 75 | E10: =0.5*D10 -> 37.5 | G10: =0.5*F10 -> 0 | H10: =E10+G10 -> 37.5 | I10: =RANK(H10,$H$4:$H$32) -> 24 | J10: =IF(H10>79.5, 1, IF(H10>69.5, 2, IF(H10>59.5, 3, IF(H10>54.5, 4, IF(H10>49.5, 5, IF(H10>44.5, 6, IF(H10>39.5, 7, IF(H10>33.5, 8, IF(H10>-1, 9))))))))) -> 8 | K10: =VLOOKUP(H10,'GRADING SYSTEM'!$D$15:$F$23,3) -> WEAK PASS
A11: ='Info List'!A10 -> BHS9008 | B11: ='Info List'!B10 -> BAAH JOSEPHINE KONADU | C11: ='Info List'!C10 -> 9 | D11: 76 | E11: =0.5*D11 -> 38 | G11: =0.5*F11 -> 0 | H11: =E11+G11 -> 38 | I11: =RANK(H11,$H$4:$H$32) -> 23 | J11: =IF(H11>79.5, 1, IF(H11>69.5, 2, IF(H11>59.5, 3, IF(H11>54.5, 4, IF(H11>49.5, 5, IF(H11>44.5, 6, IF(H11>39.5, 7, IF(H11>33.5, 8, IF(H11>-1, 9))))))))) -> 8 | K11: =VLOOKUP(H11,'GRADING SYSTEM'!$D$15:$F$23,3) -> WEAK PASS
A12: ='Info List'!A11 -> BHS9009 | B12: ='Info List'!B11 -> BAIDOO MIDRED | C12: ='Info List'!C11 -> 9 | D12: 77 | E12: =0.5*D12 -> 38.5 | G12: =0.5*F12 -> 0 | H12: =E12+G12 -> 38.5 | I12: =RANK(H12,$H$4:$H$32) -> 22 | J12: =IF(H12>79.5, 1, IF(H12>69.5, 2, IF(H12>59.5, 3, IF(H12>54.5, 4, IF(H12>49.5, 5, IF(H12>44.5, 6, IF(H12>39.5, 7, IF(H12>33.5, 8, IF(H12>-1, 9))))))))) -> 8 | K12: =VLOOKUP(H12,'GRADING SYSTEM'!$D$15:$F$23,3) -> WEAK PASS
A13: ='Info List'!A12 -> BHS9010 | B13: ='Info List'!B12 -> BOAKYE KELVIN OWUSU | C13: ='Info List'!C12 -> 9 | D13: 78 | E13: =0.5*D13 -> 39 | G13: =0.5*F13 -> 0 | H13: =E13+G13 -> 39 | I13: =RANK(H13,$H$4:$H$32) -> 21 | J13: =IF(H13>79.5, 1, IF(H13>69.5, 2, IF(H13>59.5, 3, IF(H13>54.5, 4, IF(H13>49.5, 5, IF(H13>44.5, 6, IF(H13>39.5, 7, IF(H13>33.5, 8, IF(H13>-1, 9))))))))) -> 8 | K13: =VLOOKUP(H13,'GRADING SYSTEM'!$D$15:$F$23,3) -> WEAK PASS
A14: ='Info List'!A13 -> BHS9011 | B14: ='Info List'!B13 -> BOATENG NICHOLAS KELVIN | C14: ='Info List'!C13 -> 9 | D14: 79 | E14: =0.5*D14 -> 39.5 | G14: =0.5*F14 -> 0 | H14: =E14+G14 -> 39.5 | I14: =RANK(H14,$H$4:$H$32) -> 20 | J14: =IF(H14>79.5, 1, IF(H14>69.5, 2, IF(H14>59.5, 3, IF(H14>54.5, 4, IF(H14>49.5, 5, IF(H14>44.5, 6, IF(H14>39.5, 7, IF(H14>33.5, 8, IF(H14>-1, 9))))))))) -> 8 | K14: =VLOOKUP(H14,'GRADING SYSTEM'!$D$15:$F$23,3) -> WEAK PASS
A15: ='Info List'!A14 -> BHS9012 | B15: ='Info List'!B14 -> CHARKITEY JOSEPH TETTEY EMEKOH | C15: ='Info List'!C14 -> 9 | D15: 80 | E15: =0.5*D15 -> 40 | G15: =0.5*F15 -> 0 | H15: =E15+G15 -> 40 | I15: =RANK(H15,$H$4:$H$32) -> 19 | J15: =IF(H15>79.5, 1, IF(H15>69.5, 2, IF(H15>59.5, 3, IF(H15>54.5, 4, IF(H15>49.5, 5, IF(H15>44.5, 6, IF(H15>39.5, 7, IF(H15>33.5, 8, IF(H15>-1, 9))))))))) -> 7 | K15: =VLOOKUP(H15,'GRADING SYSTEM'!$D$15:$F$23,3) -> PASS
A16: ='Info List'!A15 -> BHS9013 | B16: ='Info List'!B15 -> DANKWAH AMA JANEL | C16: ='Info List'!C15 -> 9 | D16: 81 | E16: =0.5*D16 -> 40.5 | G16: =0.5*F16 -> 0 | H16: =E16+G16 -> 40.5 | I16: =RANK(H16,$H$4:$H$32) -> 18 | J16: =IF(H16>79.5, 1, IF(H16>69.5, 2, IF(H16>59.5, 3, IF(H16>54.5, 4, IF(H16>49.5, 5, IF(H16>44.5, 6, IF(H16>39.5, 7, IF(H16>33.5, 8, IF(H16>-1, 9))))))))) -> 7 | K16: =VLOOKUP(H16,'GRADING SYSTEM'!$D$15:$F$23,3) -> PASS
... A32: ='Info List'!A31 -> BHS9029 | B32: ='Info List'!B31 -> YEVAKPOR SYLVIA EYRAM | C32: ='Info List'!C31 -> 9 | D32: 97 | E32: =0.5*D32 -> 48.5 | G32: =0.5*F32 -> 0 | H32: =E32+G32 -> 48.5 | I32: =RANK(H32,$H$4:$H$32) -> 2 | J32: =IF(H32>79.5, 1, IF(H32>69.5, 2, IF(H32>59.5, 3, IF(H32>54.5, 4, IF(H32>49.5, 5, IF(H32>44.5, 6, IF(H32>39.5, 7, IF(H32>33.5, 8, IF(H32>-1, 9))))))))) -> 6 | K32: =VLOOKUP(H32,'GRADING SYSTEM'!$D$15:$F$23,3) -> LOW AVERAGE

Sheet SCIENCE
A1: SCIENCE
A2: ID | B2: NAME OF STUDENT | C2: FORM | D2: TOTAL | E2: CLASS SCORE | F2: TOTAL EXAMS SCORE | G2: EXAMS SCORE | H2: OVERALL SCORE | I2: POSITION IN SUBJECT | J2: GRADE | K2: REMARKS
D3: 1 | E3: 50% (A) | F3: 1 | G3: 50% (B) | H3: 100% (A + B)
A4: ='Info List'!A3 -> BHS9001 | B4: ='Info List'!B3 -> ABRAKWAH EVA OWUSUAA | C4: ='Info List'!C3 -> 9 | D4: 80 | E4: =0.5*D4 -> 40 | F4: 90 | G4: =0.5*F4 -> 45 | H4: =E4+G4 -> 85 | I4: =RANK(H4,$H$4:$H$32) -> 1 | J4: =IF(H4>79.5, 1, IF(H4>69.5, 2, IF(H4>59.5, 3, IF(H4>54.5, 4, IF(H4>49.5, 5, IF(H4>44.5, 6, IF(H4>39.5, 7, IF(H4>33.5, 8, IF(H4>-1, 9))))))))) -> 1 | K4: =VLOOKUP(H4,'GRADING SYSTEM'!$D$15:$F$23,3) -> EXCELLENT
A5: ='Info List'!A4 -> BHS9002 | B5: ='Info List'!B4 -> ADZILAFU EDWARD | C5: ='Info List'!C4 -> 9 | D5: 70 | E5: =0.5*D5 -> 35 | G5: =0.5*F5 -> 0 | H5: =E5+G5 -> 35 | I5: =RANK(H5,$H$4:$H$32) -> 29 | J5: =IF(H5>79.5, 1, IF(H5>69.5, 2, IF(H5>59.5, 3, IF(H5>54.5, 4, IF(H5>49.5, 5, IF(H5>44.5, 6, IF(H5>39.5, 7, IF(H5>33.5, 8, IF(H5>-1, 9))))))))) -> 8 | K5: =VLOOKUP(H5,'GRADING SYSTEM'!$D$15:$F$23,3) -> WEAK PASS
A6: ='Info List'!A5 -> BHS9003 | B6: ='Info List'!B5 -> AGYEPONG DASEBRE | C6: ='Info List'!C5 -> 9 | D6: 71 | E6: =0.5*D6 -> 35.5 | G6: =0.5*F6 -> 0 | H6: =E6+G6 -> 35.5 | I6: =RANK(H6,$H$4:$H$32) -> 28 | J6: =IF(H6>79.5, 1, IF(H6>69.5, 2, IF(H6>59.5, 3, IF(H6>54.5, 4, IF(H6>49.5, 5, IF(H6>44.5, 6, IF(H6>39.5, 7, IF(H6>33.5, 8, IF(H6>-1, 9))))))))) -> 8 | K6: =VLOOKUP(H6,'GRADING SYSTEM'!$D$15:$F$23,3) -> WEAK PASS
A7: ='Info List'!A6 -> BHS9004 | B7: ='Info List'!B6 -> ANIWA JOANA SEYRAM | C7: ='Info List'!C6 -> 9 | D7: 72 | E7: =0.5*D7 -> 36 | G7: =0.5*F7 -> 0 | H7: =E7+G7 -> 36 | I7: =RANK(H7,$H$4:$H$32) -> 27 | J7: =IF(H7>79.5, 1, IF(H7>69.5, 2, IF(H7>59.5, 3, IF(H7>54.5, 4, IF(H7>49.5, 5, IF(H7>44.5, 6, IF(H7>39.5, 7, IF(H7>33.5, 8, IF(H7>-1, 9))))))))) -> 8 | K7: =VLOOKUP(H7,'GRADING SYSTEM'!$D$15:$F$23,3) -> WEAK PASS
A8: ='Info List'!A7 -> BHS9005 | B8: ='Info List'!B7 -> ANNAN AGNES | C8: ='Info List'!C7 -> 9 | D8: 73 | E8: =0.5*D8 -> 36.5 | G8: =0.5*F8 -> 0 | H8: =E8+G8 -> 36.5 | I8: =RANK(H8,$H$4:$H$32) -> 26 | J8: =IF(H8>79.5, 1, IF(H8>69.5, 2, IF(H8>59.5, 3, IF(H8>54.5, 4, IF(H8>49.5, 5, IF(H8>44.5, 6, IF(H8>39.5, 7, IF(H8>33.5, 8, IF(H8>-1, 9))))))))) -> 8 | K8: =VLOOKUP(H8,'GRADING SYSTEM'!$D$15:$F$23,3) -> WEAK PASS
A9: ='Info List'!A8 -> BHS9006 | B9: ='Info List'!B8 -> ARTHUR LILLIAN ABENA | C9: ='Info List'!C8 -> 9 | D9: 74 | E9: =0.5*D9 -> 37 | G9: =0.5*F9 -> 0 | H9: =E9+G9 -> 37 | I9: =RANK(H9,$H$4:$H$32) -> 25 | J9: =IF(H9>79.5, 1, IF(H9>69.5, 2, IF(H9>59.5, 3, IF(H9>54.5, 4, IF(H9>49.5, 5, IF(H9>44.5, 6, IF(H9>39.5, 7, IF(H9>33.5, 8, IF(H9>-1, 9))))))))) -> 8 | K9: =VLOOKUP(H9,'GRADING SYSTEM'!$D$15:$F$23,3) -> WEAK PASS
A10: ='Info List'!A9 -> BHS9007 | B10: ='Info List'!B9 -> ASARE JACOB | C10: ='Info List'!C9 -> 9 | D10: 75 | E10: =0.5*D10 -> 37.5 | G10: =0.5*F10 -> 0 | H10: =E10+G10 -> 37.5 | I10: =RANK(H10,$H$4:$H$32) -> 24 | J10: =IF(H10>79.5, 1, IF(H10>69.5, 2, IF(H10>59.5, 3, IF(H10>54.5, 4, IF(H10>49.5, 5, IF(H10>44.5, 6, IF(H10>39.5, 7, IF(H10>33.5, 8, IF(H10>-1, 9))))))))) -> 8 | K10: =VLOOKUP(H10,'GRADING SYSTEM'!$D$15:$F$23,3) -> WEAK PASS
A11: ='Info List'!A10 -> BHS9008 | B11: ='Info List'!B10 -> BAAH JOSEPHINE KONADU | C11: ='Info List'!C10 -> 9 | D11: 76 | E11: =0.5*D11 -> 38 | G11: =0.5*F11 -> 0 | H11: =E11+G11 -> 38 | I11: =RANK(H11,$H$4:$H$32) -> 23 | J11: =IF(H11>79.5, 1, IF(H11>69.5, 2, IF(H11>59.5, 3, IF(H11>54.5, 4, IF(H11>49.5, 5, IF(H11>44.5, 6, IF(H11>39.5, 7, IF(H11>33.5, 8, IF(H11>-1, 9))))))))) -> 8 | K11: =VLOOKUP(H11,'GRADING SYSTEM'!$D$15:$F$23,3) -> WEAK PASS
A12: ='Info List'!A11 -> BHS9009 | B12: ='Info List'!B11 -> BAIDOO MIDRED | C12: ='Info List'!C11 -> 9 | D12: 77 | E12: =0.5*D12 -> 38.5 | G12: =0.5*F12 -> 0 | H12: =E12+G12 -> 38.5 | I12: =RANK(H12,$H$4:$H$32) -> 22 | J12: =IF(H12>79.5, 1, IF(H12>69.5, 2, IF(H12>59.5, 3, IF(H12>54.5, 4, IF(H12>49.5, 5, IF(H12>44.5, 6, IF(H12>39.5, 7, IF(H12>33.5, 8, IF(H12>-1, 9))))))))) -> 8 | K12: =VLOOKUP(H12,'GRADING SYSTEM'!$D$15:$F$23,3) -> WEAK PASS
A13: ='Info List'!A12 -> BHS9010 | B13: ='Info List'!B12 -> BOAKYE KELVIN OWUSU | C13: ='Info List'!C12 -> 9 | D13: 78 | E13: =0.5*D13 -> 39 | G13: =0.5*F13 -> 0 | H13: =E13+G13 -> 39 | I13: =RANK(H13,$H$4:$H$32) -> 21 | J13: =IF(H13>79.5, 1, IF(H13>69.5, 2, IF(H13>59.5, 3, IF(H13>54.5, 4, IF(H13>49.5, 5, IF(H13>44.5, 6, IF(H13>39.5, 7, IF(H13>33.5, 8, IF(H13>-1, 9))))))))) -> 8 | K13: =VLOOKUP(H13,'GRADING SYSTEM'!$D$15:$F$23,3) -> WEAK PASS
A14: ='Info List'!A13 -> BHS9011 | B14: ='Info List'!B13 -> BOATENG NICHOLAS KELVIN | C14: ='Info List'!C13 -> 9 | D14: 79 | E14: =0.5*D14 -> 39.5 | G14: =0.5*F14 -> 0 | H14: =E14+G14 -> 39.5 | I14: =RANK(H14,$H$4:$H$32) -> 20 | J14: =IF(H14>79.5, 1, IF(H14>69.5, 2, IF(H14>59.5, 3, IF(H14>54.5, 4, IF(H14>49.5, 5, IF(H14>44.5, 6, IF(H14>39.5, 7, IF(H14>33.5, 8, IF(H14>-1, 9))))))))) -> 8 | K14: =VLOOKUP(H14,'GRADING SYSTEM'!$D$15:$F$23,3) -> WEAK PASS
A15: ='Info List'!A14 -> BHS9012 | B15: ='Info List'!B14 -> CHARKITEY JOSEPH TETTEY EMEKOH | C15: ='Info List'!C14 -> 9 | D15: 80 | E15: =0.5*D15 -> 40 | G15: =0.5*F15 -> 0 | H15: =E15+G15 -> 40 | I15: =RANK(H15,$H$4:$H$32) -> 19 | J15: =IF(H15>79.5, 1, IF(H15>69.5, 2, IF(H15>59.5, 3, IF(H15>54.5, 4, IF(H15>49.5, 5, IF(H15>44.5, 6, IF(H15>39.5, 7, IF(H15>33.5, 8, IF(H15>-1, 9))))))))) -> 7 | K15: =VLOOKUP(H15,'GRADING SYSTEM'!$D$15:$F$23,3) -> PASS
A16: ='Info List'!A15 -> BHS9013 | B16: ='Info List'!B15 -> DANKWAH AMA JANEL | C16: ='Info List'!C15 -> 9 | D16: 81 | E16: =0.5*D16 -> 40.5 | G16: =0.5*F16 -> 0 | H16: =E16+G16 -> 40.5 | I16: =RANK(H16,$H$4:$H$32) -> 18 | J16: =IF(H16>79.5, 1, IF(H16>69.5, 2, IF(H16>59.5, 3, IF(H16>54.5, 4, IF(H16>49.5, 5, IF(H16>44.5, 6, IF(H16>39.5, 7, IF(H16>33.5, 8, IF(H16>-1, 9))))))))) -> 7 | K16: =VLOOKUP(H16,'GRADING SYSTEM'!$D$15:$F$23,3) -> PASS
... A32: ='Info List'!A31 -> BHS9029 | B32: ='Info List'!B31 -> YEVAKPOR SYLVIA EYRAM | C32: ='Info List'!C31 -> 9 | D32: 97 | E32: =0.5*D32 -> 48.5 | G32: =0.5*F32 -> 0 | H32: =E32+G32 -> 48.5 | I32: =RANK(H32,$H$4:$H$32) -> 2 | J32: =IF(H32>79.5, 1, IF(H32>69.5, 2, IF(H32>59.5, 3, IF(H32>54.5, 4, IF(H32>49.5, 5, IF(H32>44.5, 6, IF(H32>39.5, 7, IF(H32>33.5, 8, IF(H32>-1, 9))))))))) -> 6 | K32: =VLOOKUP(H32,'GRADING SYSTEM'!$D$15:$F$23,3) -> LOW AVERAGE

Sheet SOCIAL
A1: SOCIAL STUDIES
A2: ID | B2: NAME OF STUDENT | C2: FORM | D2: TOTAL | E2: CLASS SCORE | F2: TOTAL EXAMS SCORE | G2: EXAMS SCORE | H2: OVERALL SCORE | I2: POSITION IN SUBJECT | J2: GRADE | K2: REMARKS
D3: 1 | E3: 50% (A) | F3: 1 | G3: 50% (B) | H3: 100% (A + B)
A4: ='Info List'!A3 -> BHS9001 | B4: ='Info List'!B3 -> ABRAKWAH EVA OWUSUAA | C4: ='Info List'!C3 -> 9 | D4: 86 | E4: =0.5*D4 -> 43 | F4: 81 | G4: =0.5*F4 -> 40.5 | H4: =E4+G4 -> 83.5 | I4: =RANK(H4,$H$4:$H$32) -> 1 | J4: =IF(H4>79.5, 1, IF(H4>69.5, 2, IF(H4>59.5, 3, IF(H4>54.5, 4, IF(H4>49.5, 5, IF(H4>44.5, 6, IF(H4>39.5, 7, IF(H4>33.5, 8, IF(H4>-1, 9))))))))) -> 1 | K4: =VLOOKUP(H4,'GRADING SYSTEM'!$D$15:$F$23,3) -> EXCELLENT
A5: ='Info List'!A4 -> BHS9002 | B5: ='Info List'!B4 -> ADZILAFU EDWARD | C5: ='Info List'!C4 -> 9 | D5: 70 | E5: =0.5*D5 -> 35 | G5: =0.5*F5 -> 0 | H5: =E5+G5 -> 35 | I5: =RANK(H5,$H$4:$H$32) -> 29 | J5: =IF(H5>79.5, 1, IF(H5>69.5, 2, IF(H5>59.5, 3, IF(H5>54.5, 4, IF(H5>49.5, 5, IF(H5>44.5, 6, IF(H5>39.5, 7, IF(H5>33.5, 8, IF(H5>-1, 9))))))))) -> 8 | K5: =VLOOKUP(H5,'GRADING SYSTEM'!$D$15:$F$23,3) -> WEAK PASS
A6: ='Info List'!A5 -> BHS9003 | B6: ='Info List'!B5 -> AGYEPONG DASEBRE | C6: ='Info List'!C5 -> 9 | D6: 71 | E6: =0.5*D6 -> 35.5 | G6: =0.5*F6 -> 0 | H6: =E6+G6 -> 35.5 | I6: =RANK(H6,$H$4:$H$32) -> 28 | J6: =IF(H6>79.5, 1, IF(H6>69.5, 2, IF(H6>59.5, 3, IF(H6>54.5, 4, IF(H6>49.5, 5, IF(H6>44.5, 6, IF(H6>39.5, 7, IF(H6>33.5, 8, IF(H6>-1, 9))))))))) -> 8 | K6: =VLOOKUP(H6,'GRADING SYSTEM'!$D$15:$F$23,3) -> WEAK PASS
A7: ='Info List'!A6 -> BHS9004 | B7: ='Info List'!B6 -> ANIWA JOANA SEYRAM | C7: ='Info List'!C6 -> 9 | D7: 72 | E7: =0.5*D7 -> 36 | G7: =0.5*F7 -> 0 | H7: =E7+G7 -> 36 | I7: =RANK(H7,$H$4:$H$32) -> 27 | J7: =IF(H7>79.5, 1, IF(H7>69.5, 2, IF(H7>59.5, 3, IF(H7>54.5, 4, IF(H7>49.5, 5, IF(H7>44.5, 6, IF(H7>39.5, 7, IF(H7>33.5, 8, IF(H7>-1, 9))))))))) -> 8 | K7: =VLOOKUP(H7,'GRADING SYSTEM'!$D$15:$F$23,3) -> WEAK PASS
A8: ='Info List'!A7 -> BHS9005 | B8: ='Info List'!B7 -> ANNAN AGNES | C8: ='Info List'!C7 -> 9 | D8: 73 | E8: =0.5*D8 -> 36.5 | G8: =0.5*F8 -> 0 | H8: =E8+G8 -> 36.5 | I8: =RANK(H8,$H$4:$H$32) -> 26 | J8: =IF(H8>79.5, 1, IF(H8>69.5, 2, IF(H8>59.5, 3, IF(H8>54.5, 4, IF(H8>49.5, 5, IF(H8>44.5, 6, IF(H8>39.5, 7, IF(H8>33.5, 8, IF(H8>-1, 9))))))))) -> 8 | K8: =VLOOKUP(H8,'GRADING SYSTEM'!$D$15:$F$23,3) -> WEAK PASS
A9: ='Info List'!A8 -> BHS9006 | B9: ='Info List'!B8 -> ARTHUR LILLIAN ABENA | C9: ='Info List'!C8 -> 9 | D9: 74 | E9: =0.5*D9 -> 37 | G9: =0.5*F9 -> 0 | H9: =E9+G9 -> 37 | I9: =RANK(H9,$H$4:$H$32) -> 25 | J9: =IF(H9>79.5, 1, IF(H9>69.5, 2, IF(H9>59.5, 3, IF(H9>54.5, 4, IF(H9>49.5, 5, IF(H9>44.5, 6, IF(H9>39.5, 7, IF(H9>33.5, 8, IF(H9>-1, 9))))))))) -> 8 | K9: =VLOOKUP(H9,'GRADING SYSTEM'!$D$15:$F$23,3) -> WEAK PASS
A10: ='Info List'!A9 -> BHS9007 | B10: ='Info List'!B9 -> ASARE JACOB | C10: ='Info List'!C9 -> 9 | D10: 75 | E10: =0.5*D10 -> 37.5 | G10: =0.5*F10 -> 0 | H10: =E10+G10 -> 37.5 | I10: =RANK(H10,$H$4:$H$32) -> 24 | J10: =IF(H10>79.5, 1, IF(H10>69.5, 2, IF(H10>59.5, 3, IF(H10>54.5, 4, IF(H10>49.5, 5, IF(H10>44.5, 6, IF(H10>39.5, 7, IF(H10>33.5, 8, IF(H10>-1, 9))))))))) -> 8 | K10: =VLOOKUP(H10,'GRADING SYSTEM'!$D$15:$F$23,3) -> WEAK PASS
A11: ='Info List'!A10 -> BHS9008 | B11: ='Info List'!B10 -> BAAH JOSEPHINE KONADU | C11: ='Info List'!C10 -> 9 | D11: 76 | E11: =0.5*D11 -> 38 | G11: =0.5*F11 -> 0 | H11: =E11+G11 -> 38 | I11: =RANK(H11,$H$4:$H$32) -> 23 | J11: =IF(H11>79.5, 1, IF(H11>69.5, 2, IF(H11>59.5, 3, IF(H11>54.5, 4, IF(H11>49.5, 5, IF(H11>44.5, 6, IF(H11>39.5, 7, IF(H11>33.5, 8, IF(H11>-1, 9))))))))) -> 8 | K11: =VLOOKUP(H11,'GRADING SYSTEM'!$D$15:$F$23,3) -> WEAK PASS
A12: ='Info List'!A11 -> BHS9009 | B12: ='Info List'!B11 -> BAIDOO MIDRED | C12: ='Info List'!C11 -> 9 | D12: 77 | E12: =0.5*D12 -> 38.5 | G12: =0.5*F12 -> 0 | H12: =E12+G12 -> 38.5 | I12: =RANK(H12,$H$4:$H$32) -> 22 | J12: =IF(H12>79.5, 1, IF(H12>69.5, 2, IF(H12>59.5, 3, IF(H12>54.5, 4, IF(H12>49.5, 5, IF(H12>44.5, 6, IF(H12>39.5, 7, IF(H12>33.5, 8, IF(H12>-1, 9))))))))) -> 8 | K12: =VLOOKUP(H12,'GRADING SYSTEM'!$D$15:$F$23,3) -> WEAK PASS
A13: ='Info List'!A12 -> BHS9010 | B13: ='Info List'!B12 -> BOAKYE KELVIN OWUSU | C13: ='Info List'!C12 -> 9 | D13: 78 | E13: =0.5*D13 -> 39 | G13: =0.5*F13 -> 0 | H13: =E13+G13 -> 39 | I13: =RANK(H13,$H$4:$H$32) -> 21 | J13: =IF(H13>79.5, 1, IF(H13>69.5, 2, IF(H13>59.5, 3, IF(H13>54.5, 4, IF(H13>49.5, 5, IF(H13>44.5, 6, IF(H13>39.5, 7, IF(H13>33.5, 8, IF(H13>-1, 9))))))))) -> 8 | K13: =VLOOKUP(H13,'GRADING SYSTEM'!$D$15:$F$23,3) -> WEAK PASS
A14: ='Info List'!A13 -> BHS9011 | B14: ='Info List'!B13 -> BOATENG NICHOLAS KELVIN | C14: ='Info List'!C13 -> 9 | D14: 79 | E14: =0.5*D14 -> 39.5 | G14: =0.5*F14 -> 0 | H14: =E14+G14 -> 39.5 | I14: =RANK(H14,$H$4:$H$32) -> 20 | J14: =IF(H14>79.5, 1, IF(H14>69.5, 2, IF(H14>59.5, 3, IF(H14>54.5, 4, IF(H14>49.5, 5, IF(H14>44.5, 6, IF(H14>39.5, 7, IF(H14>33.5, 8, IF(H14>-1, 9))))))))) -> 8 | K14: =VLOOKUP(H14,'GRADING SYSTEM'!$D$15:$F$23,3) -> WEAK PASS
A15: ='Info List'!A14 -> BHS9012 | B15: ='Info List'!B14 -> CHARKITEY JOSEPH TETTEY EMEKOH | C15: ='Info List'!C14 -> 9 | D15: 80 | E15: =0.5*D15 -> 40 | G15: =0.5*F15 -> 0 | H15: =E15+G15 -> 40 | I15: =RANK(H15,$H$4:$H$32) -> 19 | J15: =IF(H15>79.5, 1, IF(H15>69.5, 2, IF(H15>59.5, 3, IF(H15>54.5, 4, IF(H15>49.5, 5, IF(H15>44.5, 6, IF(H15>39.5, 7, IF(H15>33.5, 8, IF(H15>-1, 9))))))))) -> 7 | K15: =VLOOKUP(H15,'GRADING SYSTEM'!$D$15:$F$23,3) -> PASS
A16: ='Info List'!A15 -> BHS9013 | B16: ='Info List'!B15 -> DANKWAH AMA JANEL | C16: ='Info List'!C15 -> 9 | D16: 81 | E16: =0.5*D16 -> 40.5 | G16: =0.5*F16 -> 0 | H16: =E16+G16 -> 40.5 | I16: =RANK(H16,$H$4:$H$32) -> 18 | J16: =IF(H16>79.5, 1, IF(H16>69.5, 2, IF(H16>59.5, 3, IF(H16>54.5, 4, IF(H16>49.5, 5, IF(H16>44.5, 6, IF(H16>39.5, 7, IF(H16>33.5, 8, IF(H16>-1, 9))))))))) -> 7 | K16: =VLOOKUP(H16,'GRADING SYSTEM'!$D$15:$F$23,3) -> PASS
... A32: ='Info List'!A31 -> BHS9029 | B32: ='Info List'!B31 -> YEVAKPOR SYLVIA EYRAM | C32: ='Info List'!C31 -> 9 | D32: 97 | E32: =0.5*D32 -> 48.5 | G32: =0.5*F32 -> 0 | H32: =E32+G32 -> 48.5 | I32: =RANK(H32,$H$4:$H$32) -> 2 | J32: =IF(H32>79.5, 1, IF(H32>69.5, 2, IF(H32>59.5, 3, IF(H32>54.5, 4, IF(H32>49.5, 5, IF(H32>44.5, 6, IF(H32>39.5, 7, IF(H32>33.5, 8, IF(H32>-1, 9))))))))) -> 6 | K32: =VLOOKUP(H32,'GRADING SYSTEM'!$D$15:$F$23,3) -> LOW AVERAGE

Sheet R.M.E
A1: RELIGIOUS AND MORAL EDUCATION
A2: ID | B2: NAME OF STUDENT | C2: FORM | D2: TOTAL | E2: CLASS SCORE | F2: TOTAL EXAMS SCORE | G2: EXAMS SCORE | H2: OVERALL SCORE | I2: POSITION IN SUBJECT | J2: GRADE | K2: REMARKS
D3: 1 | E3: 50% (A) | F3: 1 | G3: 50% (B) | H3: 100% (A + B)
A4: ='Info List'!A3 -> BHS9001 | B4: ='Info List'!B3 -> ABRAKWAH EVA OWUSUAA | C4: ='Info List'!C3 -> 9 | D4: 91 | E4: =0.5*D4 -> 45.5 | F4: 70 | G4: =0.5*F4 -> 35 | H4: =E4+G4 -> 80.5 | I4: =RANK(H4,$H$4:$H$32) -> 1 | J4: =IF(H4>79.5, 1, IF(H4>69.5, 2, IF(H4>59.5, 3, IF(H4>54.5, 4, IF(H4>49.5, 5, IF(H4>44.5, 6, IF(H4>39.5, 7, IF(H4>33.5, 8, IF(H4>-1, 9))))))))) -> 1 | K4: =VLOOKUP(H4,'GRADING SYSTEM'!$D$15:$F$23,3) -> EXCELLENT
A5: ='Info List'!A4 -> BHS9002 | B5: ='Info List'!B4 -> ADZILAFU EDWARD | C5: ='Info List'!C4 -> 9 | E5: =0.5*D5 -> 0 | G5: =0.5*F5 -> 0 | H5: =E5+G5 -> 0 | I5: =RANK(H5,$H$4:$H$32) -> 2 | J5: =IF(H5>79.5, 1, IF(H5>69.5, 2, IF(H5>59.5, 3, IF(H5>54.5, 4, IF(H5>49.5, 5, IF(H5>44.5, 6, IF(H5>39.5, 7, IF(H5>33.5, 8, IF(H5>-1, 9))))))))) -> 9 | K5: =VLOOKUP(H5,'GRADING SYSTEM'!$D$15:$F$23,3) -> FAIL
A6: ='Info List'!A5 -> BHS9003 | B6: ='Info List'!B5 -> AGYEPONG DASEBRE | C6: ='Info List'!C5 -> 9 | E6: =0.5*D6 -> 0 | G6: =0.5*F6 -> 0 | H6: =E6+G6 -> 0 | I6: =RANK(H6,$H$4:$H$32) -> 2 | J6: =IF(H6>79.5, 1, IF(H6>69.5, 2, IF(H6>59.5, 3, IF(H6>54.5, 4, IF(H6>49.5, 5, IF(H6>44.5, 6, IF(H6>39.5, 7, IF(H6>33.5, 8, IF(H6>-1, 9))))))))) -> 9 | K6: =VLOOKUP(H6,'GRADING SYSTEM'!$D$15:$F$23,3) -> FAIL
A7: ='Info List'!A6 -> BHS9004 | B7: ='Info List'!B6 -> ANIWA JOANA SEYRAM | C7: ='Info List'!C6 -> 9 | E7: =0.5*D7 -> 0 | G7: =0.5*F7 -> 0 | H7: =E7+G7 -> 0 | I7: =RANK(H7,$H$4:$H$32) -> 2 | J7: =IF(H7>79.5, 1, IF(H7>69.5, 2, IF(H7>59.5, 3, IF(H7>54.5, 4, IF(H7>49.5, 5, IF(H7>44.5, 6, IF(H7>39.5, 7, IF(H7>33.5, 8, IF(H7>-1, 9))))))))) -> 9 | K7: =VLOOKUP(H7,'GRADING SYSTEM'!$D$15:$F$23,3) -> FAIL
A8: ='Info List'!A7 -> BHS9005 | B8: ='Info List'!B7 -> ANNAN AGNES | C8: ='Info List'!C7 -> 9 | E8: =0.5*D8 -> 0 | G8: =0.5*F8 -> 0 | H8: =E8+G8 -> 0 | I8: =RANK(H8,$H$4:$H$32) -> 2 | J8: =IF(H8>79.5, 1, IF(H8>69.5, 2, IF(H8>59.5, 3, IF(H8>54.5, 4, IF(H8>49.5, 5, IF(H8>44.5, 6, IF(H8>39.5, 7, IF(H8>33.5, 8, IF(H8>-1, 9))))))))) -> 9 | K8: =VLOOKUP(H8,'GRADING SYSTEM'!$D$15:$F$23,3) -> FAIL
A9: ='Info List'!A8 -> BHS9006 | B9: ='Info List'!B8 -> ARTHUR LILLIAN ABENA | C9: ='Info List'!C8 -> 9 | E9: =0.5*D9 -> 0 | G9: =0.5*F9 -> 0 | H9: =E9+G9 -> 0 | I9: =RANK(H9,$H$4:$H$32) -> 2 | J9: =IF(H9>79.5, 1, IF(H9>69.5, 2, IF(H9>59.5, 3, IF(H9>54.5, 4, IF(H9>49.5, 5, IF(H9>44.5, 6, IF(H9>39.5, 7, IF(H9>33.5, 8, IF(H9>-1, 9))))))))) -> 9 | K9: =VLOOKUP(H9,'GRADING SYSTEM'!$D$15:$F$23,3) -> FAIL
A10: ='Info List'!A9 -> BHS9007 | B10: ='Info List'!B9 -> ASARE JACOB | C10: ='Info List'!C9 -> 9 | E10: =0.5*D10 -> 0 | G10: =0.5*F10 -> 0 | H10: =E10+G10 -> 0 | I10: =RANK(H10,$H$4:$H$32) -> 2 | J10: =IF(H10>79.5, 1, IF(H10>69.5, 2, IF(H10>59.5, 3, IF(H10>54.5, 4, IF(H10>49.5, 5, IF(H10>44.5, 6, IF(H10>39.5, 7, IF(H10>33.5, 8, IF(H10>-1, 9))))))))) -> 9 | K10: =VLOOKUP(H10,'GRADING SYSTEM'!$D$15:$F$23,3) -> FAIL
A11: ='Info List'!A10 -> BHS9008 | B11: ='Info List'!B10 -> BAAH JOSEPHINE KONADU | C11: ='Info List'!C10 -> 9 | E11: =0.5*D11 -> 0 | G11: =0.5*F11 -> 0 | H11: =E11+G11 -> 0 | I11: =RANK(H11,$H$4:$H$32) -> 2 | J11: =IF(H11>79.5, 1, IF(H11>69.5, 2, IF(H11>59.5, 3, IF(H11>54.5, 4, IF(H11>49.5, 5, IF(H11>44.5, 6, IF(H11>39.5, 7, IF(H11>33.5, 8, IF(H11>-1, 9))))))))) -> 9 | K11: =VLOOKUP(H11,'GRADING SYSTEM'!$D$15:$F$23,3) -> FAIL
A12: ='Info List'!A11 -> BHS9009 | B12: ='Info List'!B11 -> BAIDOO MIDRED | C12: ='Info List'!C11 -> 9 | E12: =0.5*D12 -> 0 | G12: =0.5*F12 -> 0 | H12: =E12+G12 -> 0 | I12: =RANK(H12,$H$4:$H$32) -> 2 | J12: =IF(H12>79.5, 1, IF(H12>69.5, 2, IF(H12>59.5, 3, IF(H12>54.5, 4, IF(H12>49.5, 5, IF(H12>44.5, 6, IF(H12>39.5, 7, IF(H12>33.5, 8, IF(H12>-1, 9))))))))) -> 9 | K12: =VLOOKUP(H12,'GRADING SYSTEM'!$D$15:$F$23,3) -> FAIL
A13: ='Info List'!A12 -> BHS9010 | B13: ='Info List'!B12 -> BOAKYE KELVIN OWUSU | C13: ='Info List'!C12 -> 9 | E13: =0.5*D13 -> 0 | G13: =0.5*F13 -> 0 | H13: =E13+G13 -> 0 | I13: =RANK(H13,$H$4:$H$32) -> 2 | J13: =IF(H13>79.5, 1, IF(H13>69.5, 2, IF(H13>59.5, 3, IF(H13>54.5, 4, IF(H13>49.5, 5, IF(H13>44.5, 6, IF(H13>39.5, 7, IF(H13>33.5, 8, IF(H13>-1, 9))))))))) -> 9 | K13: =VLOOKUP(H13,'GRADING SYSTEM'!$D$15:$F$23,3) -> FAIL
A14: ='Info List'!A13 -> BHS9011 | B14: ='Info List'!B13 -> BOATENG NICHOLAS KELVIN | C14: ='Info List'!C13 -> 9 | E14: =0.5*D14 -> 0 | G14: =0.5*F14 -> 0 | H14: =E14+G14 -> 0 | I14: =RANK(H14,$H$4:$H$32) -> 2 | J14: =IF(H14>79.5, 1, IF(H14>69.5, 2, IF(H14>59.5, 3, IF(H14>54.5, 4, IF(H14>49.5, 5, IF(H14>44.5, 6, IF(H14>39.5, 7, IF(H14>33.5, 8, IF(H14>-1, 9))))))))) -> 9 | K14: =VLOOKUP(H14,'GRADING SYSTEM'!$D$15:$F$23,3) -> FAIL
A15: ='Info List'!A14 -> BHS9012 | B15: ='Info List'!B14 -> CHARKITEY JOSEPH TETTEY EMEKOH | C15: ='Info List'!C14 -> 9 | E15: =0.5*D15 -> 0 | G15: =0.5*F15 -> 0 | H15: =E15+G15 -> 0 | I15: =RANK(H15,$H$4:$H$32) -> 2 | J15: =IF(H15>79.5, 1, IF(H15>69.5, 2, IF(H15>59.5, 3, IF(H15>54.5, 4, IF(H15>49.5, 5, IF(H15>44.5, 6, IF(H15>39.5, 7, IF(H15>33.5, 8, IF(H15>-1, 9))))))))) -> 9 | K15: =VLOOKUP(H15,'GRADING SYSTEM'!$D$15:$F$23,3) -> FAIL
A16: ='Info List'!A15 -> BHS9013 | B16: ='Info List'!B15 -> DANKWAH AMA JANEL | C16: ='Info List'!C15 -> 9 | E16: =0.5*D16 -> 0 | G16: =0.5*F16 -> 0 | H16: =E16+G16 -> 0 | I16: =RANK(H16,$H$4:$H$32) -> 2 | J16: =IF(H16>79.5, 1, IF(H16>69.5, 2, IF(H16>59.5, 3, IF(H16>54.5, 4, IF(H16>49.5, 5, IF(H16>44.5, 6, IF(H16>39.5, 7, IF(H16>33.5, 8, IF(H16>-1, 9))))))))) -> 9 | K16: =VLOOKUP(H16,'GRADING SYSTEM'!$D$15:$F$23,3) -> FAIL
... A32: ='Info List'!A31 -> BHS9029 | B32: ='Info List'!B31 -> YEVAKPOR SYLVIA EYRAM | C32: ='Info List'!C31 -> 9 | E32: =0.5*D32 -> 0 | G32: =0.5*F32 -> 0 | H32: =E32+G32 -> 0 | I32: =RANK(H32,$H$4:$H$32) -> 2 | J32: =IF(H32>79.5, 1, IF(H32>69.5, 2, IF(H32>59.5, 3, IF(H32>54.5, 4, IF(H32>49.5, 5, IF(H32>44.5, 6, IF(H32>39.5, 7, IF(H32>33.5, 8, IF(H32>-1, 9))))))))) -> 9 | K32: =VLOOKUP(H32,'GRADING SYSTEM'!$D$15:$F$23,3) -> FAIL

Sheet COMPUTING
A1: COMPUTING
A2: ID | B2: NAME OF STUDENT | C2: FORM | D2: TOTAL | E2: CLASS SCORE | F2: TOTAL EXAMS SCORE | G2: EXAMS SCORE | H2: OVERALL SCORE | I2: POSITION IN SUBJECT | J2: GRADE | K2: REMARKS
D3: 1 | E3: 50% (A) | F3: 1 | G3: 50% (B) | H3: 100% (A + B)
A4: ='Info List'!A3 -> BHS9001 | B4: ='Info List'!B3 -> ABRAKWAH EVA OWUSUAA | C4: ='Info List'!C3 -> 9 | D4: 98 | E4: =0.5*D4 -> 49 | F4: 94 | G4: =0.5*F4 -> 47 | H4: =E4+G4 -> 96 | I4: =RANK(H4,$H$4:$H$32) -> 1 | J4: =IF(H4>79.5, 1, IF(H4>69.5, 2, IF(H4>59.5, 3, IF(H4>54.5, 4, IF(H4>49.5, 5, IF(H4>44.5, 6, IF(H4>39.5, 7, IF(H4>33.5, 8, IF(H4>-1, 9))))))))) -> 1 | K4: =VLOOKUP(H4,'GRADING SYSTEM'!$D$15:$F$23,3) -> EXCELLENT
A5: ='Info List'!A4 -> BHS9002 | B5: ='Info List'!B4 -> ADZILAFU EDWARD | C5: ='Info List'!C4 -> 9 | E5: =0.5*D5 -> 0 | G5: =0.5*F5 -> 0 | H5: =E5+G5 -> 0 | I5: =RANK(H5,$H$4:$H$32) -> 2 | J5: =IF(H5>79.5, 1, IF(H5>69.5, 2, IF(H5>59.5, 3, IF(H5>54.5, 4, IF(H5>49.5, 5, IF(H5>44.5, 6, IF(H5>39.5, 7, IF(H5>33.5, 8, IF(H5>-1, 9))))))))) -> 9 | K5: =VLOOKUP(H5,'GRADING SYSTEM'!$D$15:$F$23,3) -> FAIL
A6: ='Info List'!A5 -> BHS9003 | B6: ='Info List'!B5 -> AGYEPONG DASEBRE | C6: ='Info List'!C5 -> 9 | E6: =0.5*D6 -> 0 | G6: =0.5*F6 -> 0 | H6: =E6+G6 -> 0 | I6: =RANK(H6,$H$4:$H$32) -> 2 | J6: =IF(H6>79.5, 1, IF(H6>69.5, 2, IF(H6>59.5, 3, IF(H6>54.5, 4, IF(H6>49.5, 5, IF(H6>44.5, 6, IF(H6>39.5, 7, IF(H6>33.5, 8, IF(H6>-1, 9))))))))) -> 9 | K6: =VLOOKUP(H6,'GRADING SYSTEM'!$D$15:$F$23,3) -> FAIL
A7: ='Info List'!A6 -> BHS9004 | B7: ='Info List'!B6 -> ANIWA JOANA SEYRAM | C7: ='Info List'!C6 -> 9 | E7: =0.5*D7 -> 0 | G7: =0.5*F7 -> 0 | H7: =E7+G7 -> 0 | I7: =RANK(H7,$H$4:$H$32) -> 2 | J7: =IF(H7>79.5, 1, IF(H7>69.5, 2, IF(H7>59.5, 3, IF(H7>54.5, 4, IF(H7>49.5, 5, IF(H7>44.5, 6, IF(H7>39.5, 7, IF(H7>33.5, 8, IF(H7>-1, 9))))))))) -> 9 | K7: =VLOOKUP(H7,'GRADING SYSTEM'!$D$15:$F$23,3) -> FAIL
A8: ='Info List'!A7 -> BHS9005 | B8: ='Info List'!B7 -> ANNAN AGNES | C8: ='Info List'!C7 -> 9 | E8: =0.5*D8 -> 0 | G8: =0.5*F8 -> 0 | H8: =E8+G8 -> 0 | I8: =RANK(H8,$H$4:$H$32) -> 2 | J8: =IF(H8>79.5, 1, IF(H8>69.5, 2, IF(H8>59.5, 3, IF(H8>54.5, 4, IF(H8>49.5, 5, IF(H8>44.5, 6, IF(H8>39.5, 7, IF(H8>33.5, 8, IF(H8>-1, 9))))))))) -> 9 | K8: =VLOOKUP(H8,'GRADING SYSTEM'!$D$15:$F$23,3) -> FAIL
A9: ='Info List'!A8 -> BHS9006 | B9: ='Info List'!B8 -> ARTHUR LILLIAN ABENA | C9: ='Info List'!C8 -> 9 | E9: =0.5*D9 -> 0 | G9: =0.5*F9 -> 0 | H9: =E9+G9 -> 0 | I9: =RANK(H9,$H$4:$H$32) -> 2 | J9: =IF(H9>79.5, 1, IF(H9>69.5, 2, IF(H9>59.5, 3, IF(H9>54.5, 4, IF(H9>49.5, 5, IF(H9>44.5, 6, IF(H9>39.5, 7, IF(H9>33.5, 8, IF(H9>-1, 9))))))))) -> 9 | K9: =VLOOKUP(H9,'GRADING SYSTEM'!$D$15:$F$23,3) -> FAIL
A10: ='Info List'!A9 -> BHS9007 | B10: ='Info List'!B9 -> ASARE JACOB | C10: ='Info List'!C9 -> 9 | E10: =0.5*D10 -> 0 | G10: =0.5*F10 -> 0 | H10: =E10+G10 -> 0 | I10: =RANK(H10,$H$4:$H$32) -> 2 | J10: =IF(H10>79.5, 1, IF(H10>69.5, 2, IF(H10>59.5, 3, IF(H10>54.5, 4, IF(H10>49.5, 5, IF(H10>44.5, 6, IF(H10>39.5, 7, IF(H10>33.5, 8, IF(H10>-1, 9))))))))) -> 9 | K10: =VLOOKUP(H10,'GRADING SYSTEM'!$D$15:$F$23,3) -> FAIL
A11: ='Info List'!A10 -> BHS9008 | B11: ='Info List'!B10 -> BAAH JOSEPHINE KONADU | C11: ='Info List'!C10 -> 9 | E11: =0.5*D11 -> 0 | G11: =0.5*F11 -> 0 | H11: =E11+G11 -> 0 | I11: =RANK(H11,$H$4:$H$32) -> 2 | J11: =IF(H11>79.5, 1, IF(H11>69.5, 2, IF(H11>59.5, 3, IF(H11>54.5, 4, IF(H11>49.5, 5, IF(H11>44.5, 6, IF(H11>39.5, 7, IF(H11>33.5, 8, IF(H11>-1, 9))))))))) -> 9 | K11: =VLOOKUP(H11,'GRADING SYSTEM'!$D$15:$F$23,3) -> FAIL
A12: ='Info List'!A11 -> BHS9009 | B12: ='Info List'!B11 -> BAIDOO MIDRED | C12: ='Info List'!C11 -> 9 | E12: =0.5*D12 -> 0 | G12: =0.5*F12 -> 0 | H12: =E12+G12 -> 0 | I12: =RANK(H12,$H$4:$H$32) -> 2 | J12: =IF(H12>79.5, 1, IF(H12>69.5, 2, IF(H12>59.5, 3, IF(H12>54.5, 4, IF(H12>49.5, 5, IF(H12>44.5, 6, IF(H12>39.5, 7, IF(H12>33.5, 8, IF(H12>-1, 9))))))))) -> 9 | K12: =VLOOKUP(H12,'GRADING SYSTEM'!$D$15:$F$23,3) -> FAIL
A13: ='Info List'!A12 -> BHS9010 | B13: ='Info List'!B12 -> BOAKYE KELVIN OWUSU | C13: ='Info List'!C12 -> 9 | E13: =0.5*D13 -> 0 | G13: =0.5*F13 -> 0 | H13: =E13+G13 -> 0 | I13: =RANK(H13,$H$4:$H$32) -> 2 | J13: =IF(H13>79.5, 1, IF(H13>69.5, 2, IF(H13>59.5, 3, IF(H13>54.5, 4, IF(H13>49.5, 5, IF(H13>44.5, 6, IF(H13>39.5, 7, IF(H13>33.5, 8, IF(H13>-1, 9))))))))) -> 9 | K13: =VLOOKUP(H13,'GRADING SYSTEM'!$D$15:$F$23,3) -> FAIL
A14: ='Info List'!A13 -> BHS9011 | B14: ='Info List'!B13 -> BOATENG NICHOLAS KELVIN | C14: ='Info List'!C13 -> 9 | E14: =0.5*D14 -> 0 | G14: =0.5*F14 -> 0 | H14: =E14+G14 -> 0 | I14: =RANK(H14,$H$4:$H$32) -> 2 | J14: =IF(H14>79.5, 1, IF(H14>69.5, 2, IF(H14>59.5, 3, IF(H14>54.5, 4, IF(H14>49.5, 5, IF(H14>44.5, 6, IF(H14>39.5, 7, IF(H14>33.5, 8, IF(H14>-1, 9))))))))) -> 9 | K14: =VLOOKUP(H14,'GRADING SYSTEM'!$D$15:$F$23,3) -> FAIL
A15: ='Info List'!A14 -> BHS9012 | B15: ='Info List'!B14 -> CHARKITEY JOSEPH TETTEY EMEKOH | C15: ='Info List'!C14 -> 9 | E15: =0.5*D15 -> 0 | G15: =0.5*F15 -> 0 | H15: =E15+G15 -> 0 | I15: =RANK(H15,$H$4:$H$32) -> 2 | J15: =IF(H15>79.5, 1, IF(H15>69.5, 2, IF(H15>59.5, 3, IF(H15>54.5, 4, IF(H15>49.5, 5, IF(H15>44.5, 6, IF(H15>39.5, 7, IF(H15>33.5, 8, IF(H15>-1, 9))))))))) -> 9 | K15: =VLOOKUP(H15,'GRADING SYSTEM'!$D$15:$F$23,3) -> FAIL
A16: ='Info List'!A15 -> BHS9013 | B16: ='Info List'!B15 -> DANKWAH AMA JANEL | C16: ='Info List'!C15 -> 9 | E16: =0.5*D16 -> 0 | G16: =0.5*F16 -> 0 | H16: =E16+G16 -> 0 | I16: =RANK(H16,$H$4:$H$32) -> 2 | J16: =IF(H16>79.5, 1, IF(H16>69.5, 2, IF(H16>59.5, 3, IF(H16>54.5, 4, IF(H16>49.5, 5, IF(H16>44.5, 6, IF(H16>39.5, 7, IF(H16>33.5, 8, IF(H16>-1, 9))))))))) -> 9 | K16: =VLOOKUP(H16,'GRADING SYSTEM'!$D$15:$F$23,3) -> FAIL
... A32: ='Info List'!A31 -> BHS9029 | B32: ='Info List'!B31 -> YEVAKPOR SYLVIA EYRAM | C32: ='Info List'!C31 -> 9 | E32: =0.5*D32 -> 0 | G32: =0.5*F32 -> 0 | H32: =E32+G32 -> 0 | I32: =RANK(H32,$H$4:$H$32) -> 2 | J32: =IF(H32>79.5, 1, IF(H32>69.5, 2, IF(H32>59.5, 3, IF(H32>54.5, 4, IF(H32>49.5, 5, IF(H32>44.5, 6, IF(H32>39.5, 7, IF(H32>33.5, 8, IF(H32>-1, 9))))))))) -> 9 | K32: =VLOOKUP(H32,'GRADING SYSTEM'!$D$15:$F$23,3) -> FAIL

Sheet CAD
A1: CREATIVE ARTS AND DESIGN
A2: ID | B2: NAME OF STUDENT | C2: FORM | D2: TOTAL | E2: CLASS SCORE | F2: TOTAL EXAMS SCORE | G2: EXAMS SCORE | H2: OVERALL SCORE | I2: POSITION IN SUBJECT | J2: GRADE | K2: REMARKS
D3: 1 | E3: 50% (A) | F3: 1 | G3: 50% (B) | H3: 100% (A + B)
A4: ='Info List'!A3 -> BHS9001 | B4: ='Info List'!B3 -> ABRAKWAH EVA OWUSUAA | C4: ='Info List'!C3 -> 9 | D4: 76 | E4: =0.5*D4 -> 38 | F4: 82 | G4: =0.5*F4 -> 41 | H4: =E4+G4 -> 79 | I4: =RANK(H4,$H$4:$H$32) -> 1 | J4: =IF(H4>79.5, 1, IF(H4>69.5, 2, IF(H4>59.5, 3, IF(H4>54.5, 4, IF(H4>49.5, 5, IF(H4>44.5, 6, IF(H4>39.5, 7, IF(H4>33.5, 8, IF(H4>-1, 9))))))))) -> 2 | K4: =VLOOKUP(H4,'GRADING SYSTEM'!$D$15:$F$23,3) -> VERY GOOD
A5: ='Info List'!A4 -> BHS9002 | B5: ='Info List'!B4 -> ADZILAFU EDWARD | C5: ='Info List'!C4 -> 9 | E5: =0.5*D5 -> 0 | G5: =0.5*F5 -> 0 | H5: =E5+G5 -> 0 | I5: =RANK(H5,$H$4:$H$32) -> 2 | J5: =IF(H5>79.5, 1, IF(H5>69.5, 2, IF(H5>59.5, 3, IF(H5>54.5, 4, IF(H5>49.5, 5, IF(H5>44.5, 6, IF(H5>39.5, 7, IF(H5>33.5, 8, IF(H5>-1, 9))))))))) -> 9 | K5: =VLOOKUP(H5,'GRADING SYSTEM'!$D$15:$F$23,3) -> FAIL
A6: ='Info List'!A5 -> BHS9003 | B6: ='Info List'!B5 -> AGYEPONG DASEBRE | C6: ='Info List'!C5 -> 9 | E6: =0.5*D6 -> 0 | G6: =0.5*F6 -> 0 | H6: =E6+G6 -> 0 | I6: =RANK(H6,$H$4:$H$32) -> 2 | J6: =IF(H6>79.5, 1, IF(H6>69.5, 2, IF(H6>59.5, 3, IF(H6>54.5, 4, IF(H6>49.5, 5, IF(H6>44.5, 6, IF(H6>39.5, 7, IF(H6>33.5, 8, IF(H6>-1, 9))))))))) -> 9 | K6: =VLOOKUP(H6,'GRADING SYSTEM'!$D$15:$F$23,3) -> FAIL
A7: ='Info List'!A6 -> BHS9004 | B7: ='Info List'!B6 -> ANIWA JOANA SEYRAM | C7: ='Info List'!C6 -> 9 | E7: =0.5*D7 -> 0 | G7: =0.5*F7 -> 0 | H7: =E7+G7 -> 0 | I7: =RANK(H7,$H$4:$H$32) -> 2 | J7: =IF(H7>79.5, 1, IF(H7>69.5, 2, IF(H7>59.5, 3, IF(H7>54.5, 4, IF(H7>49.5, 5, IF(H7>44.5, 6, IF(H7>39.5, 7, IF(H7>33.5, 8, IF(H7>-1, 9))))))))) -> 9 | K7: =VLOOKUP(H7,'GRADING SYSTEM'!$D$15:$F$23,3) -> FAIL
A8: ='Info List'!A7 -> BHS9005 | B8: ='Info List'!B7 -> ANNAN AGNES | C8: ='Info List'!C7 -> 9 | E8: =0.5*D8 -> 0 | G8: =0.5*F8 -> 0 | H8: =E8+G8 -> 0 | I8: =RANK(H8,$H$4:$H$32) -> 2 | J8: =IF(H8>79.5, 1, IF(H8>69.5, 2, IF(H8>59.5, 3, IF(H8>54.5, 4, IF(H8>49.5, 5, IF(H8>44.5, 6, IF(H8>39.5, 7, IF(H8>33.5, 8, IF(H8>-1, 9))))))))) -> 9 | K8: =VLOOKUP(H8,'GRADING SYSTEM'!$D$15:$F$23,3) -> FAIL
A9: ='Info List'!A8 -> BHS9006 | B9: ='Info List'!B8 -> ARTHUR LILLIAN ABENA | C9: ='Info List'!C8 -> 9 | E9: =0.5*D9 -> 0 | G9: =0.5*F9 -> 0 | H9: =E9+G9 -> 0 | I9: =RANK(H9,$H$4:$H$32) -> 2 | J9: =IF(H9>79.5, 1, IF(H9>69.5, 2, IF(H9>59.5, 3, IF(H9>54.5, 4, IF(H9>49.5, 5, IF(H9>44.5, 6, IF(H9>39.5, 7, IF(H9>33.5, 8, IF(H9>-1, 9))))))))) -> 9 | K9: =VLOOKUP(H9,'GRADING SYSTEM'!$D$15:$F$23,3) -> FAIL
A10: ='Info List'!A9 -> BHS9007 | B10: ='Info List'!B9 -> ASARE JACOB | C10: ='Info List'!C9 -> 9 | E10: =0.5*D10 -> 0 | G10: =0.5*F10 -> 0 | H10: =E10+G10 -> 0 | I10: =RANK(H10,$H$4:$H$32) -> 2 | J10: =IF(H10>79.5, 1, IF(H10>69.5, 2, IF(H10>59.5, 3, IF(H10>54.5, 4, IF(H10>49.5, 5, IF(H10>44.5, 6, IF(H10>39.5, 7, IF(H10>33.5, 8, IF(H10>-1, 9))))))))) -> 9 | K10: =VLOOKUP(H10,'GRADING SYSTEM'!$D$15:$F$23,3) -> FAIL
A11: ='Info List'!A10 -> BHS9008 | B11: ='Info List'!B10 -> BAAH JOSEPHINE KONADU | C11: ='Info List'!C10 -> 9 | E11: =0.5*D11 -> 0 | G11: =0.5*F11 -> 0 | H11: =E11+G11 -> 0 | I11: =RANK(H11,$H$4:$H$32) -> 2 | J11: =IF(H11>79.5, 1, IF(H11>69.5, 2, IF(H11>59.5, 3, IF(H11>54.5, 4, IF(H11>49.5, 5, IF(H11>44.5, 6, IF(H11>39.5, 7, IF(H11>33.5, 8, IF(H11>-1, 9))))))))) -> 9 | K11: =VLOOKUP(H11,'GRADING SYSTEM'!$D$15:$F$23,3) -> FAIL
A12: ='Info List'!A11 -> BHS9009 | B12: ='Info List'!B11 -> BAIDOO MIDRED | C12: ='Info List'!C11 -> 9 | E12: =0.5*D12 -> 0 | G12: =0.5*F12 -> 0 | H12: =E12+G12 -> 0 | I12: =RANK(H12,$H$4:$H$32) -> 2 | J12: =IF(H12>79.5, 1, IF(H12>69.5, 2, IF(H12>59.5, 3, IF(H12>54.5, 4, IF(H12>49.5, 5, IF(H12>44.5, 6, IF(H12>39.5, 7, IF(H12>33.5, 8, IF(H12>-1, 9))))))))) -> 9 | K12: =VLOOKUP(H12,'GRADING SYSTEM'!$D$15:$F$23,3) -> FAIL
A13: ='Info List'!A12 -> BHS9010 | B13: ='Info List'!B12 -> BOAKYE KELVIN OWUSU | C13: ='Info List'!C12 -> 9 | E13: =0.5*D13 -> 0 | G13: =0.5*F13 -> 0 | H13: =E13+G13 -> 0 | I13: =RANK(H13,$H$4:$H$32) -> 2 | J13: =IF(H13>79.5, 1, IF(H13>69.5, 2, IF(H13>59.5, 3, IF(H13>54.5, 4, IF(H13>49.5, 5, IF(H13>44.5, 6, IF(H13>39.5, 7, IF(H13>33.5, 8, IF(H13>-1, 9))))))))) -> 9 | K13: =VLOOKUP(H13,'GRADING SYSTEM'!$D$15:$F$23,3) -> FAIL
A14: ='Info List'!A13 -> BHS9011 | B14: ='Info List'!B13 -> BOATENG NICHOLAS KELVIN | C14: ='Info List'!C13 -> 9 | E14: =0.5*D14 -> 0 | G14: =0.5*F14 -> 0 | H14: =E14+G14 -> 0 | I14: =RANK(H14,$H$4:$H$32) -> 2 | J14: =IF(H14>79.5, 1, IF(H14>69.5, 2, IF(H14>59.5, 3, IF(H14>54.5, 4, IF(H14>49.5, 5, IF(H14>44.5, 6, IF(H14>39.5, 7, IF(H14>33.5, 8, IF(H14>-1, 9))))))))) -> 9 | K14: =VLOOKUP(H14,'GRADING SYSTEM'!$D$15:$F$23,3) -> FAIL
A15: ='Info List'!A14 -> BHS9012 | B15: ='Info List'!B14 -> CHARKITEY JOSEPH TETTEY EMEKOH | C15: ='Info List'!C14 -> 9 | E15: =0.5*D15 -> 0 | G15: =0.5*F15 -> 0 | H15: =E15+G15 -> 0 | I15: =RANK(H15,$H$4:$H$32) -> 2 | J15: =IF(H15>79.5, 1, IF(H15>69.5, 2, IF(H15>59.5, 3, IF(H15>54.5, 4, IF(H15>49.5, 5, IF(H15>44.5, 6, IF(H15>39.5, 7, IF(H15>33.5, 8, IF(H15>-1, 9))))))))) -> 9 | K15: =VLOOKUP(H15,'GRADING SYSTEM'!$D$15:$F$23,3) -> FAIL
A16: ='Info List'!A15 -> BHS9013 | B16: ='Info List'!B15 -> DANKWAH AMA JANEL | C16: ='Info List'!C15 -> 9 | E16: =0.5*D16 -> 0 | G16: =0.5*F16 -> 0 | H16: =E16+G16 -> 0 | I16: =RANK(H16,$H$4:$H$32) -> 2 | J16: =IF(H16>79.5, 1, IF(H16>69.5, 2, IF(H16>59.5, 3, IF(H16>54.5, 4, IF(H16>49.5, 5, IF(H16>44.5, 6, IF(H16>39.5, 7, IF(H16>33.5, 8, IF(H16>-1, 9))))))))) -> 9 | K16: =VLOOKUP(H16,'GRADING SYSTEM'!$D$15:$F$23,3) -> FAIL
... A32: ='Info List'!A31 -> BHS9029 | B32: ='Info List'!B31 -> YEVAKPOR SYLVIA EYRAM | C32: ='Info List'!C31 -> 9 | E32: =0.5*D32 -> 0 | G32: =0.5*F32 -> 0 | H32: =E32+G32 -> 0 | I32: =RANK(H32,$H$4:$H$32) -> 2 | J32: =IF(H32>79.5, 1, IF(H32>69.5, 2, IF(H32>59.5, 3, IF(H32>54.5, 4, IF(H32>49.5, 5, IF(H32>44.5, 6, IF(H32>39.5, 7, IF(H32>33.5, 8, IF(H32>-1, 9))))))))) -> 9 | K32: =VLOOKUP(H32,'GRADING SYSTEM'!$D$15:$F$23,3) -> FAIL

Sheet CAREER
A1: CAREER TECHNOLOGY
A2: ID | B2: NAME OF STUDENT | C2: FORM | D2: TOTAL | E2: CLASS SCORE | F2: TOTAL EXAMS SCORE | G2: EXAMS SCORE | H2: OVERALL SCORE | I2: POSITION IN SUBJECT | J2: GRADE | K2: REMARKS
D3: 1 | E3: 50% (A) | F3: 1 | G3: 50% (B) | H3: 100% (A + B)
A4: ='Info List'!A3 -> BHS9001 | B4: ='Info List'!B3 -> ABRAKWAH EVA OWUSUAA | C4: ='Info List'!C3 -> 9 | D4: 88 | E4: =0.5*D4 -> 44 | F4: 86 | G4: =0.5*F4 -> 43 | H4: =E4+G4 -> 87 | I4: =RANK(H4,$H$4:$H$32) -> 1 | J4: =IF(H4>79.5, 1, IF(H4>69.5, 2, IF(H4>59.5, 3, IF(H4>54.5, 4, IF(H4>49.5, 5, IF(H4>44.5, 6, IF(H4>39.5, 7, IF(H4>33.5, 8, IF(H4>-1, 9))))))))) -> 1 | K4: =VLOOKUP(H4,'GRADING SYSTEM'!$D$15:$F$23,3) -> EXCELLENT
A5: ='Info List'!A4 -> BHS9002 | B5: ='Info List'!B4 -> ADZILAFU EDWARD | C5: ='Info List'!C4 -> 9 | E5: =0.5*D5 -> 0 | G5: =0.5*F5 -> 0 | H5: =E5+G5 -> 0 | I5: =RANK(H5,$H$4:$H$32) -> 2 | J5: =IF(H5>79.5, 1, IF(H5>69.5, 2, IF(H5>59.5, 3, IF(H5>54.5, 4, IF(H5>49.5, 5, IF(H5>44.5, 6, IF(H5>39.5, 7, IF(H5>33.5, 8, IF(H5>-1, 9))))))))) -> 9 | K5: =VLOOKUP(H5,'GRADING SYSTEM'!$D$15:$F$23,3) -> FAIL
A6: ='Info List'!A5 -> BHS9003 | B6: ='Info List'!B5 -> AGYEPONG DASEBRE | C6: ='Info List'!C5 -> 9 | E6: =0.5*D6 -> 0 | G6: =0.5*F6 -> 0 | H6: =E6+G6 -> 0 | I6: =RANK(H6,$H$4:$H$32) -> 2 | J6: =IF(H6>79.5, 1, IF(H6>69.5, 2, IF(H6>59.5, 3, IF(H6>54.5, 4, IF(H6>49.5, 5, IF(H6>44.5, 6, IF(H6>39.5, 7, IF(H6>33.5, 8, IF(H6>-1, 9))))))))) -> 9 | K6: =VLOOKUP(H6,'GRADING SYSTEM'!$D$15:$F$23,3) -> FAIL
A7: ='Info List'!A6 -> BHS9004 | B7: ='Info List'!B6 -> ANIWA JOANA SEYRAM | C7: ='Info List'!C6 -> 9 | E7: =0.5*D7 -> 0 | G7: =0.5*F7 -> 0 | H7: =E7+G7 -> 0 | I7: =RANK(H7,$H$4:$H$32) -> 2 | J7: =IF(H7>79.5, 1, IF(H7>69.5, 2, IF(H7>59.5, 3, IF(H7>54.5, 4, IF(H7>49.5, 5, IF(H7>44.5, 6, IF(H7>39.5, 7, IF(H7>33.5, 8, IF(H7>-1, 9))))))))) -> 9 | K7: =VLOOKUP(H7,'GRADING SYSTEM'!$D$15:$F$23,3) -> FAIL
A8: ='Info List'!A7 -> BHS9005 | B8: ='Info List'!B7 -> ANNAN AGNES | C8: ='Info List'!C7 -> 9 | E8: =0.5*D8 -> 0 | G8: =0.5*F8 -> 0 | H8: =E8+G8 -> 0 | I8: =RANK(H8,$H$4:$H$32) -> 2 | J8: =IF(H8>79.5, 1, IF(H8>69.5, 2, IF(H8>59.5, 3, IF(H8>54.5, 4, IF(H8>49.5, 5, IF(H8>44.5, 6, IF(H8>39.5, 7, IF(H8>33.5, 8, IF(H8>-1, 9))))))))) -> 9 | K8: =VLOOKUP(H8,'GRADING SYSTEM'!$D$15:$F$23,3) -> FAIL
A9: ='Info List'!A8 -> BHS9006 | B9: ='Info List'!B8 -> ARTHUR LILLIAN ABENA | C9: ='Info List'!C8 -> 9 | E9: =0.5*D9 -> 0 | G9: =0.5*F9 -> 0 | H9: =E9+G9 -> 0 | I9: =RANK(H9,$H$4:$H$32) -> 2 | J9: =IF(H9>79.5, 1, IF(H9>69.5, 2, IF(H9>59.5, 3, IF(H9>54.5, 4, IF(H9>49.5, 5, IF(H9>44.5, 6, IF(H9>39.5, 7, IF(H9>33.5, 8, IF(H9>-1, 9))))))))) -> 9 | K9: =VLOOKUP(H9,'GRADING SYSTEM'!$D$15:$F$23,3) -> FAIL
A10: ='Info List'!A9 -> BHS9007 | B10: ='Info List'!B9 -> ASARE JACOB | C10: ='Info List'!C9 -> 9 | E10: =0.5*D10 -> 0 | G10: =0.5*F10 -> 0 | H10: =E10+G10 -> 0 | I10: =RANK(H10,$H$4:$H$32) -> 2 | J10: =IF(H10>79.5, 1, IF(H10>69.5, 2, IF(H10>59.5, 3, IF(H10>54.5, 4, IF(H10>49.5, 5, IF(H10>44.5, 6, IF(H10>39.5, 7, IF(H10>33.5, 8, IF(H10>-1, 9))))))))) -> 9 | K10: =VLOOKUP(H10,'GRADING SYSTEM'!$D$15:$F$23,3) -> FAIL
A11: ='Info List'!A10 -> BHS9008 | B11: ='Info List'!B10 -> BAAH JOSEPHINE KONADU | C11: ='Info List'!C10 -> 9 | E11: =0.5*D11 -> 0 | G11: =0.5*F11 -> 0 | H11: =E11+G11 -> 0 | I11: =RANK(H11,$H$4:$H$32) -> 2 | J11: =IF(H11>79.5, 1, IF(H11>69.5, 2, IF(H11>59.5, 3, IF(H11>54.5, 4, IF(H11>49.5, 5, IF(H11>44.5, 6, IF(H11>39.5, 7, IF(H11>33.5, 8, IF(H11>-1, 9))))))))) -> 9 | K11: =VLOOKUP(H11,'GRADING SYSTEM'!$D$15:$F$23,3) -> FAIL
A12: ='Info List'!A11 -> BHS9009 | B12: ='Info List'!B11 -> BAIDOO MIDRED | C12: ='Info List'!C11 -> 9 | E12: =0.5*D12 -> 0 | G12: =0.5*F12 -> 0 | H12: =E12+G12 -> 0 | I12: =RANK(H12,$H$4:$H$32) -> 2 | J12: =IF(H12>79.5, 1, IF(H12>69.5, 2, IF(H12>59.5, 3, IF(H12>54.5, 4, IF(H12>49.5, 5, IF(H12>44.5, 6, IF(H12>39.5, 7, IF(H12>33.5, 8, IF(H12>-1, 9))))))))) -> 9 | K12: =VLOOKUP(H12,'GRADING SYSTEM'!$D$15:$F$23,3) -> FAIL
A13: ='Info List'!A12 -> BHS9010 | B13: ='Info List'!B12 -> BOAKYE KELVIN OWUSU | C13: ='Info List'!C12 -> 9 | E13: =0.5*D13 -> 0 | G13: =0.5*F13 -> 0 | H13: =E13+G13 -> 0 | I13: =RANK(H13,$H$4:$H$32) -> 2 | J13: =IF(H13>79.5, 1, IF(H13>69.5, 2, IF(H13>59.5, 3, IF(H13>54.5, 4, IF(H13>49.5, 5, IF(H13>44.5, 6, IF(H13>39.5, 7, IF(H13>33.5, 8, IF(H13>-1, 9))))))))) -> 9 | K13: =VLOOKUP(H13,'GRADING SYSTEM'!$D$15:$F$23,3) -> FAIL
A14: ='Info List'!A13 -> BHS9011 | B14: ='Info List'!B13 -> BOATENG NICHOLAS KELVIN | C14: ='Info List'!C13 -> 9 | E14: =0.5*D14 -> 0 | G14: =0.5*F14 -> 0 | H14: =E14+G14 -> 0 | I14: =RANK(H14,$H$4:$H$32) -> 2 | J14: =IF(H14>79.5, 1, IF(H14>69.5, 2, IF(H14>59.5, 3, IF(H14>54.5, 4, IF(H14>49.5, 5, IF(H14>44.5, 6, IF(H14>39.5, 7, IF(H14>33.5, 8, IF(H14>-1, 9))))))))) -> 9 | K14: =VLOOKUP(H14,'GRADING SYSTEM'!$D$15:$F$23,3) -> FAIL
A15: ='Info List'!A14 -> BHS9012 | B15: ='Info List'!B14 -> CHARKITEY JOSEPH TETTEY EMEKOH | C15: ='Info List'!C14 -> 9 | E15: =0.5*D15 -> 0 | G15: =0.5*F15 -> 0 | H15: =E15+G15 -> 0 | I15: =RANK(H15,$H$4:$H$32) -> 2 | J15: =IF(H15>79.5, 1, IF(H15>69.5, 2, IF(H15>59.5, 3, IF(H15>54.5, 4, IF(H15>49.5, 5, IF(H15>44.5, 6, IF(H15>39.5, 7, IF(H15>33.5, 8, IF(H15>-1, 9))))))))) -> 9 | K15: =VLOOKUP(H15,'GRADING SYSTEM'!$D$15:$F$23,3) -> FAIL
A16: ='Info List'!A15 -> BHS9013 | B16: ='Info List'!B15 -> DANKWAH AMA JANEL | C16: ='Info List'!C15 -> 9 | E16: =0.5*D16 -> 0 | G16: =0.5*F16 -> 0 | H16: =E16+G16 -> 0 | I16: =RANK(H16,$H$4:$H$32) -> 2 | J16: =IF(H16>79.5, 1, IF(H16>69.5, 2, IF(H16>59.5, 3, IF(H16>54.5, 4, IF(H16>49.5, 5, IF(H16>44.5, 6, IF(H16>39.5, 7, IF(H16>33.5, 8, IF(H16>-1, 9))))))))) -> 9 | K16: =VLOOKUP(H16,'GRADING SYSTEM'!$D$15:$F$23,3) -> FAIL
... A32: ='Info List'!A31 -> BHS9029 | B32: ='Info List'!B31 -> YEVAKPOR SYLVIA EYRAM | C32: ='Info List'!C31 -> 9 | E32: =0.5*D32 -> 0 | G32: =0.5*F32 -> 0 | H32: =E32+G32 -> 0 | I32: =RANK(H32,$H$4:$H$32) -> 2 | J32: =IF(H32>79.5, 1, IF(H32>69.5, 2, IF(H32>59.5, 3, IF(H32>54.5, 4, IF(H32>49.5, 5, IF(H32>44.5, 6, IF(H32>39.5, 7, IF(H32>33.5, 8, IF(H32>-1, 9))))))))) -> 9 | K32: =VLOOKUP(H32,'GRADING SYSTEM'!$D$15:$F$23,3) -> FAIL

Sheet FANTE
A1: FANTE
A2: ID | B2: NAME OF STUDENT | C2: FORM | D2: TOTAL | E2: CLASS SCORE | F2: TOTAL EXAMS SCORE | G2: EXAMS SCORE | H2: OVERALL SCORE | I2: POSITION IN SUBJECT | J2: GRADE | K2: REMARKS
D3: 1 | E3: 50% (A) | F3: 1 | G3: 50% (B) | H3: 100% (A + B)
A4: ='Info List'!A3 -> BHS9001 | B4: ='Info List'!B3 -> ABRAKWAH EVA OWUSUAA | C4: ='Info List'!C3 -> 9 | D4: 83 | E4: =0.5*D4 -> 41.5 | F4: 80 | G4: =0.5*F4 -> 40 | H4: =E4+G4 -> 81.5 | I4: =RANK(H4,$H$4:$H$32) -> 1 | J4: =IF(H4>79.5, 1, IF(H4>69.5, 2, IF(H4>59.5, 3, IF(H4>54.5, 4, IF(H4>49.5, 5, IF(H4>44.5, 6, IF(H4>39.5, 7, IF(H4>33.5, 8, IF(H4>-1, 9))))))))) -> 1 | K4: =VLOOKUP(H4,'GRADING SYSTEM'!$D$15:$F$23,3) -> EXCELLENT
A5: ='Info List'!A4 -> BHS9002 | B5: ='Info List'!B4 -> ADZILAFU EDWARD | C5: ='Info List'!C4 -> 9 | E5: =0.5*D5 -> 0 | G5: =0.5*F5 -> 0 | H5: =E5+G5 -> 0 | I5: =RANK(H5,$H$4:$H$32) -> 2 | J5: =IF(H5>79.5, 1, IF(H5>69.5, 2, IF(H5>59.5, 3, IF(H5>54.5, 4, IF(H5>49.5, 5, IF(H5>44.5, 6, IF(H5>39.5, 7, IF(H5>33.5, 8, IF(H5>-1, 9))))))))) -> 9 | K5: =VLOOKUP(H5,'GRADING SYSTEM'!$D$15:$F$23,3) -> FAIL
A6: ='Info List'!A5 -> BHS9003 | B6: ='Info List'!B5 -> AGYEPONG DASEBRE | C6: ='Info List'!C5 -> 9 | E6: =0.5*D6 -> 0 | G6: =0.5*F6 -> 0 | H6: =E6+G6 -> 0 | I6: =RANK(H6,$H$4:$H$32) -> 2 | J6: =IF(H6>79.5, 1, IF(H6>69.5, 2, IF(H6>59.5, 3, IF(H6>54.5, 4, IF(H6>49.5, 5, IF(H6>44.5, 6, IF(H6>39.5, 7, IF(H6>33.5, 8, IF(H6>-1, 9))))))))) -> 9 | K6: =VLOOKUP(H6,'GRADING SYSTEM'!$D$15:$F$23,3) -> FAIL
A7: ='Info List'!A6 -> BHS9004 | B7: ='Info List'!B6 -> ANIWA JOANA SEYRAM | C7: ='Info List'!C6 -> 9 | E7: =0.5*D7 -> 0 | G7: =0.5*F7 -> 0 | H7: =E7+G7 -> 0 | I7: =RANK(H7,$H$4:$H$32) -> 2 | J7: =IF(H7>79.5, 1, IF(H7>69.5, 2, IF(H7>59.5, 3, IF(H7>54.5, 4, IF(H7>49.5, 5, IF(H7>44.5, 6, IF(H7>39.5, 7, IF(H7>33.5, 8, IF(H7>-1, 9))))))))) -> 9 | K7: =VLOOKUP(H7,'GRADING SYSTEM'!$D$15:$F$23,3) -> FAIL
A8: ='Info List'!A7 -> BHS9005 | B8: ='Info List'!B7 -> ANNAN AGNES | C8: ='Info List'!C7 -> 9 | E8: =0.5*D8 -> 0 | G8: =0.5*F8 -> 0 | H8: =E8+G8 -> 0 | I8: =RANK(H8,$H$4:$H$32) -> 2 | J8: =IF(H8>79.5, 1, IF(H8>69.5, 2, IF(H8>59.5, 3, IF(H8>54.5, 4, IF(H8>49.5, 5, IF(H8>44.5, 6, IF(H8>39.5, 7, IF(H8>33.5, 8, IF(H8>-1, 9))))))))) -> 9 | K8: =VLOOKUP(H8,'GRADING SYSTEM'!$D$15:$F$23,3) -> FAIL
A9: ='Info List'!A8 -> BHS9006 | B9: ='Info List'!B8 -> ARTHUR LILLIAN ABENA | C9: ='Info List'!C8 -> 9 | E9: =0.5*D9 -> 0 | G9: =0.5*F9 -> 0 | H9: =E9+G9 -> 0 | I9: =RANK(H9,$H$4:$H$32) -> 2 | J9: =IF(H9>79.5, 1, IF(H9>69.5, 2, IF(H9>59.5, 3, IF(H9>54.5, 4, IF(H9>49.5, 5, IF(H9>44.5, 6, IF(H9>39.5, 7, IF(H9>33.5, 8, IF(H9>-1, 9))))))))) -> 9 | K9: =VLOOKUP(H9,'GRADING SYSTEM'!$D$15:$F$23,3) -> FAIL
A10: ='Info List'!A9 -> BHS9007 | B10: ='Info List'!B9 -> ASARE JACOB | C10: ='Info List'!C9 -> 9 | E10: =0.5*D10 -> 0 | G10: =0.5*F10 -> 0 | H10: =E10+G10 -> 0 | I10: =RANK(H10,$H$4:$H$32) -> 2 | J10: =IF(H10>79.5, 1, IF(H10>69.5, 2, IF(H10>59.5, 3, IF(H10>54.5, 4, IF(H10>49.5, 5, IF(H10>44.5, 6, IF(H10>39.5, 7, IF(H10>33.5, 8, IF(H10>-1, 9))))))))) -> 9 | K10: =VLOOKUP(H10,'GRADING SYSTEM'!$D$15:$F$23,3) -> FAIL
A11: ='Info List'!A10 -> BHS9008 | B11: ='Info List'!B10 -> BAAH JOSEPHINE KONADU | C11: ='Info List'!C10 -> 9 | E11: =0.5*D11 -> 0 | G11: =0.5*F11 -> 0 | H11: =E11+G11 -> 0 | I11: =RANK(H11,$H$4:$H$32) -> 2 | J11: =IF(H11>79.5, 1, IF(H11>69.5, 2, IF(H11>59.5, 3, IF(H11>54.5, 4, IF(H11>49.5, 5, IF(H11>44.5, 6, IF(H11>39.5, 7, IF(H11>33.5, 8, IF(H11>-1, 9))))))))) -> 9 | K11: =VLOOKUP(H11,'GRADING SYSTEM'!$D$15:$F$23,3) -> FAIL
A12: ='Info List'!A11 -> BHS9009 | B12: ='Info List'!B11 -> BAIDOO MIDRED | C12: ='Info List'!C11 -> 9 | E12: =0.5*D12 -> 0 | G12: =0.5*F12 -> 0 | H12: =E12+G12 -> 0 | I12: =RANK(H12,$H$4:$H$32) -> 2 | J12: =IF(H12>79.5, 1, IF(H12>69.5, 2, IF(H12>59.5, 3, IF(H12>54.5, 4, IF(H12>49.5, 5, IF(H12>44.5, 6, IF(H12>39.5, 7, IF(H12>33.5, 8, IF(H12>-1, 9))))))))) -> 9 | K12: =VLOOKUP(H12,'GRADING SYSTEM'!$D$15:$F$23,3) -> FAIL
A13: ='Info List'!A12 -> BHS9010 | B13: ='Info List'!B12 -> BOAKYE KELVIN OWUSU | C13: ='Info List'!C12 -> 9 | E13: =0.5*D13 -> 0 | G13: =0.5*F13 -> 0 | H13: =E13+G13 -> 0 | I13: =RANK(H13,$H$4:$H$32) -> 2 | J13: =IF(H13>79.5, 1, IF(H13>69.5, 2, IF(H13>59.5, 3, IF(H13>54.5, 4, IF(H13>49.5, 5, IF(H13>44.5, 6, IF(H13>39.5, 7, IF(H13>33.5, 8, IF(H13>-1, 9))))))))) -> 9 | K13: =VLOOKUP(H13,'GRADING SYSTEM'!$D$15:$F$23,3) -> FAIL
A14: ='Info List'!A13 -> BHS9011 | B14: ='Info List'!B13 -> BOATENG NICHOLAS KELVIN | C14: ='Info List'!C13 -> 9 | E14: =0.5*D14 -> 0 | G14: =0.5*F14 -> 0 | H14: =E14+G14 -> 0 | I14: =RANK(H14,$H$4:$H$32) -> 2 | J14: =IF(H14>79.5, 1, IF(H14>69.5, 2, IF(H14>59.5, 3, IF(H14>54.5, 4, IF(H14>49.5, 5, IF(H14>44.5, 6, IF(H14>39.5, 7, IF(H14>33.5, 8, IF(H14>-1, 9))))))))) -> 9 | K14: =VLOOKUP(H14,'GRADING SYSTEM'!$D$15:$F$23,3) -> FAIL
A15: ='Info List'!A14 -> BHS9012 | B15: ='Info List'!B14 -> CHARKITEY JOSEPH TETTEY EMEKOH | C15: ='Info List'!C14 -> 9 | E15: =0.5*D15 -> 0 | G15: =0.5*F15 -> 0 | H15: =E15+G15 -> 0 | I15: =RANK(H15,$H$4:$H$32) -> 2 | J15: =IF(H15>79.5, 1, IF(H15>69.5, 2, IF(H15>59.5, 3, IF(H15>54.5, 4, IF(H15>49.5, 5, IF(H15>44.5, 6, IF(H15>39.5, 7, IF(H15>33.5, 8, IF(H15>-1, 9))))))))) -> 9 | K15: =VLOOKUP(H15,'GRADING SYSTEM'!$D$15:$F$23,3) -> FAIL
A16: ='Info List'!A15 -> BHS9013 | B16: ='Info List'!B15 -> DANKWAH AMA JANEL | C16: ='Info List'!C15 -> 9 | E16: =0.5*D16 -> 0 | G16: =0.5*F16 -> 0 | H16: =E16+G16 -> 0 | I16: =RANK(H16,$H$4:$H$32) -> 2 | J16: =IF(H16>79.5, 1, IF(H16>69.5, 2, IF(H16>59.5, 3, IF(H16>54.5, 4, IF(H16>49.5, 5, IF(H16>44.5, 6, IF(H16>39.5, 7, IF(H16>33.5, 8, IF(H16>-1, 9))))))))) -> 9 | K16: =VLOOKUP(H16,'GRADING SYSTEM'!$D$15:$F$23,3) -> FAIL
... A32: ='Info List'!A31 -> BHS9029 | B32: ='Info List'!B31 -> YEVAKPOR SYLVIA EYRAM | C32: ='Info List'!C31 -> 9 | E32: =0.5*D32 -> 0 | G32: =0.5*F32 -> 0 | H32: =E32+G32 -> 0 | I32: =RANK(H32,$H$4:$H$32) -> 2 | J32: =IF(H32>79.5, 1, IF(H32>69.5, 2, IF(H32>59.5, 3, IF(H32>54.5, 4, IF(H32>49.5, 5, IF(H32>44.5, 6, IF(H32>39.5, 7, IF(H32>33.5, 8, IF(H32>-1, 9))))))))) -> 9 | K32: =VLOOKUP(H32,'GRADING SYSTEM'!$D$15:$F$23,3) -> FAIL

Sheet GRADING SYSTEM
A1: SCORE | B1: HEADMASTER'S REMARKS | J1: CLASS TEACHER'S REMARKS
A2: 0 | B2: Below average, must buck up. | J2: Below average, you must work hard. There is the need for parental support.
A3: 400 | B3: Below average, must buck up. | J3: Below average, you must work hard. There is the need for parental support.
A4: 450 | B4: Must work hard. | J4: You must sit up.
A5: 500 | B5: Average performance | J5: There is more room for improvement.
A6: 600 | B6: Good, can do better. | J6: Well done, but you can do better.
A7: 650 | B7: Good, can still do better. | J7: Good, keep working hard.
A8: 700 | B8: Very good, keep working hard | J8: Good work done, keep improving.
A9: 750 | B9: Excellent, keep it up. Do not rest on your oars. | J9: Excellent, keep it up.
A10: 800 | B10: That's an impressive performance, soar higher. | J10: Excellent, performance.
D13: GENERAL GRADING SYSTEM
D14: SCORE | E14: GRADE | F14: REMARKS
D15: 0 | E15: 9 | F15: FAIL
D16: 35 | E16: 8 | F16: WEAK PASS
D17: 40 | E17: 7 | F17: PASS
D18: 45 | E18: 6 | F18: LOW AVERAGE
D19: 50 | E19: 5 | F19: AVERAGE
D20: 55 | E20: 4 | F20: HIGH AVERAGE
D21: 60 | E21: 3 | F21: GOOD
D22: 70 | E22: 2 | F22: VERY GOOD
D23: 80 | E23: 1 | F23: EXCELLENT

Sheet TR ANALYSIS
